Workbook

Sheet ADVANCE
B1: November 5th, 2024
B2: ADVANCE TOTALS
B3: NAME OF OFFICE | C3: NAME OF PERSON VOTED FOR | D3: PARTY | E3: ALLODIUM | F3: BRYANT | G3: GETTYSBURG | H3: GRAHAM | I3: HAPPPY | J3: HILL CITY #1 | K3: HILL CITY #2 | L3: HILL CITY #3 | M3: HILL CITY TWP #71 | N3: HILL CITY TWP #72 | O3: NAME OF PERSON VOTED FOR | P3: PARTY | Q3: HILL CITY TWP #73 | R3: INDIANA | S3: MILLBROOK | T3: MORLAN | U3: NICODEMUS | V3: PIONEER | W3: SOLOMON | X3: WILDHORSE | Y3: TOTAL
B4: PRESIDENT AND VICE PRESIDENT | O4: PRESIDENT AND VICE PRESIDENT
C5: Trump/Vance | D5: Rep. | E5: 10 | F5: 31 | G5: 21 | H5: 11 | I5: 7 | J5: 24 | K5: 189 | L5: 57 | M5: 4 | N5: 22 | O5: Trump/Vance | P5: Rep. | Q5: 20 | R5: 3 | S5: 31 | T5: 13 | U5: 6 | V5: 10 | W5: 46 | X5: 44 | Y5: =SUM(E5:X5) -> 549
C6: Harris/Walz | D6: Dem. | E6: 0 | F6: 3 | G6: 1 | H6: 7 | I6: 8 | J6: 6 | K6: 57 | L6: 14 | M6: 0 | N6: 4 | O6: Harris/Walz | P6: Dem. | Q6: 2 | R6: 0 | S6: 6 | T6: 1 | U6: 7 | V6: 0 | W6: 6 | X6: 11 | Y6: =SUM(E6:X6) -> 133
C7: Kennedy Jr./Shanahan | D7: Indep. | E7: 0 | F7: 0 | G7: 1 | H7: 0 | I7: 0 | J7: 2 | K7: 8 | L7: 1 | M7: 0 | N7: 0 | O7: Kennedy Jr./Shanahan | P7: Indep. | Q7: 0 | R7: 1 | S7: 0 | T7: 0 | U7: 0 | V7: 0 | W7: 1 | X7: 0 | Y7: =SUM(E7:X7) -> 14
C8: Oliver/ ter Maat | D8: Lib. | E8: 0 | F8: 0 | G8: 0 | H8: 0 | I8: 0 | J8: 0 | K8: 0 | L8: 0 | M8: 0 | N8: 0 | O8: Oliver/ ter Maat | P8: Lib. | Q8: 0 | R8: 0 | S8: 0 | T8: 0 | U8: 0 | V8: 0 | W8: 0 | X8: 0 | Y8: =SUM(E8:X8) -> 0
B9: UNITED STATES REPRESENTATIVE 1ST DISTRICT | O9: UNITED STATES REPRESENTATIVE 1ST DISTRICT
C10: Paul Buskirk | D10: Dem. | E10: 0 | F10: 2 | G10: 2 | H10: 7 | I10: 6 | J10: 4 | K10: 42 | L10: 11 | M10: 0 | N10: 0 | O10: Paul Buskirk | P10: Dem. | Q10: 0 | R10: 0 | S10: 4 | T10: 0 | U10: 6 | V10: 0 | W10: 4 | X10: 7 | Y10: =SUM(E10:X10) -> 95
C11: Tracey Mann | D11: Rep. | E11: 10 | F11: 32 | G11: 22 | H11: 10 | I11: 9 | J11: 25 | K11: 186 | L11: 56 | M11: 4 | N11: 27 | O11: Tracey Mann | P11: Rep. | Q11: 22 | R11: 4 | S11: 32 | T11: 14 | U11: 7 | V11: 8 | W11: 49 | X11: 48 | Y11: =SUM(E11:X11) -> 565
B13: STATE SENATOR 40TH DISTRICT | O13: STATE SENATOR 40TH DISTRICT
C14: Richard (Rick) Billinger | D14: Rep. | E14: 10 | F14: 32 | G14: 22 | H14: 13 | I14: 13 | J14: 23 | K14: 204 | L14: 55 | M14: 4 | N14: 26 | O14: Richard (Rick) Billinger | P14: Rep. | Q14: 22 | R14: 3 | S14: 36 | T14: 14 | U14: 12 | V14: 9 | W14: 48 | X14: 49 | Y14: =SUM(E14:X14) -> 595
B15: STATE REPRESENTATIVE 110TH DISTRICT | O15: STATE REPRESENTATIVE 110TH DISTRICT
C16: ellace Henderson | D16: Dem. | E16: 0 | F16: 5 | G16: 3 | H16: 6 | I16: 7 | J16: 8 | K16: 47 | L16: 13 | M16: 0 | N16: 0 | O16: ellace Henderson | P16: Dem. | Q16: 0 | R16: 1 | S16: 5 | T16: 0 | U16: 6 | V16: 1 | W16: 6 | X16: 6 | Y16: =SUM(E16:X16) -> 114
C17: Ken Rahjes | D17: Rep. | E17: 10 | F17: 26 | G17: 21 | H17: 11 | I17: 8 | J17: 21 | K17: 175 | L17: 46 | M17: 4 | N17: 27 | O17: Ken Rahjes | P17: Rep. | Q17: 21 | R17: 3 | S17: 31 | T17: 14 | U17: 7 | V17: 7 | W17: 46 | X17: 47 | Y17: =SUM(E17:X17) -> 525
B18: DISTRICT COURT JUDGE 17TH DISTRICT 1ST DIVISION | O18: DISTRICT COURT JUDGE 17TH DISTRICT 1ST DIVISION
C19: Jesse A. Thompson | D19: Rep. | E19: 9 | F19: 32 | G19: 23 | H19: 14 | I19: 12 | J19: 25 | K19: 198 | L19: 61 | M19: 1 | N19: 25 | O19: Jesse A. Thompson | P19: Rep. | Q19: 20 | R19: 3 | S19: 35 | T19: 12 | U19: 11 | V19: 8 | W19: 46 | X19: 51 | Y19: =SUM(E19:X19) -> 586
B21: DISTRICT COURT JUDGE 17TH DISTRICT 2ND DIVISION | O21: DISTRICT COURT JUDGE 17TH DISTRICT 2ND DIVISION
C22: Paula D. Hofaker | D22: Rep. | E22: 10 | F22: 31 | G22: 21 | H22: 14 | I22: 10 | J22: 22 | K22: 189 | L22: 56 | M22: 3 | N22: 26 | O22: Paula D. Hofaker | P22: Rep. | Q22: 21 | R22: 4 | S22: 35 | T22: 13 | U22: 11 | V22: 6 | W22: 46 | X22: 50 | Y22: =SUM(E22:X22) -> 568
B23: DISTRICT MAGISTRATE JUDGE 17TH DISTRICT 1ST POSITION | O23: DISTRICT MAGISTRATE JUDGE 17TH DISTRICT 1ST POSITION
C24: Morgan Nutting | D24: Rep. | E24: 9 | F24: 31 | G24: 22 | H24: 13 | I24: 10 | J24: 28 | K24: 208 | L24: 63 | M24: 4 | N24: 23 | O24: Morgan Nutting | P24: Rep. | Q24: 20 | R24: 3 | S24: 32 | T24: 10 | U24: 10 | V24: 9 | W24: 46 | X24: 49 | Y24: =SUM(E24:X24) -> 590
B33: NAME OF OFFICE | C33: NAME OF PERSON VOTED FOR | D33: PARTY | E33: ALLODIUM | F33: BRYANT | G33: GETTYSBURG | H33: GRAHAM | I33: HAPPPY | J33: HILL CITY #1 | K33: HILL CITY #2 | L33: HILL CITY #3 | M33: HILL CITY TWP #71 | N33: HILL CITY TWP #72 | O33: NAME OF PERSON VOTED FOR | P33: PARTY | Q33: HILL CITY TWP #73 | R33: INDIANA | S33: MILLBROOK | T33: MORLAN | U33: NICODEMUS | V33: PIONEER | W33: SOLOMON | X33: WILDHORSE | Y33: TOTAL
B34: COUNTY COMMISSIONER 2ND DISTRICT | O34: COUNTY COMMISSIONER 2ND DISTRICT
C35: Jason Nelson | D35: Rep | E35: 0 | F35: 0 | G35: 0 | H35: 17 | I35: 0 | J35: 0 | K35: 182 | L35: 0 | M35: 0 | N35: 22 | O35: Jason Nelson | P35: Rep | Q35: 0 | R35: 0 | S35: 0 | T35: 0 | U35: 11 | V35: 10 | W35: 0 | X35: 0 | Y35: =E35+F35+G35+H35+I35+J35+K35+L35+M35+N35+Q35+R35+S35+T35+U35+V35+W35+X35 -> 242
Y36: =E36+F36+G36+H36+I36+J36+K36+L36+M36+N36+Q36+R36+S36+T36+U36+V36+W36+X36 -> 0
B37: COUNTY COMMISSIONER 3RD DISTRICT | O37: COUNTY COMMISSIONER 3RD DISTRICT
C38: Dan Irby | D38: Rep | E38: 0 | F38: 0 | G38: 0 | H38: 0 | I38: 16 | J38: 0 | K38: 0 | L38: 62 | M38: 0 | N38: 0 | O38: Dan Irby | P38: Rep | Q38: 19 | R38: 0 | S38: 34 | T38: 14 | U38: 0 | V38: 0 | W38: 0 | X38: 52 | Y38: =E38+F38+G38+H38+I38+J38+K38+L38+M38+N38+Q38+R38+S38+T38+U38+V38+W38+X38 -> 197
Y39: =E39+F39+G39+H39+I39+J39+K39+L39+M39+N39+Q39+R39+S39+T39+U39+V39+W39+X39 -> 0
B40: COUNTY CLERK | O40: COUNTY CLERK
C41: Kendra Robinson | D41: Rep. | E41: 10 | F41: 33 | G41: 21 | H41: 13 | I41: 14 | J41: 28 | K41: 208 | L41: 54 | M41: 2 | N41: 27 | O41: Kendra Robinson | P41: Rep. | Q41: 21 | R41: 3 | S41: 36 | T41: 13 | U41: 11 | V41: 8 | W41: 50 | X41: 54 | Y41: =E41+F41+G41+H41+I41+J41+K41+L41+M41+N41+Q41+R41+S41+T41+U41+V41+W41+X41 -> 606
B42: COUNTY TREASURER | O42: COUNTY TREASURER
C43: Jerilyn Keith | D43: Rep | E43: 10 | F43: 31 | G43: 23 | H43: 16 | I43: 14 | J43: 27 | K43: 211 | L43: 61 | M43: 3 | N43: 27 | O43: Jerilyn Keith | P43: Rep | Q43: 19 | R43: 4 | S43: 37 | T43: 13 | U43: 12 | V43: 9 | W43: 48 | X43: 52 | Y43: =E43+F43+G43+H43+I43+J43+K43+L43+M43+N43+Q43+R43+S43+T43+U43+V43+W43+X43 -> 617
Y44: =E44+F44+G44+H44+I44+J44+K44+L44+M44+N44+Q44+R44+S44+T44+U44+V44+W44+X44 -> 0
B45: COUNTY REGISTER OF DEEDS | O45: COUNTY REGISTER OF DEEDS
C46: Dani Roeder | D46: Rep | E46: 7 | F46: 26 | G46: 18 | H46: 12 | I46: 11 | J46: 18 | K46: 177 | L46: 45 | M46: 0 | N46: 7 | O46: Dani Roeder | P46: Rep | Q46: 19 | R46: 2 | S46: 24 | T46: 14 | U46: 12 | V46: 3 | W46: 32 | X46: 46 | Y46: =E46+F46+G46+H46+I46+J46+K46+L46+M46+N46+Q46+R46+S46+T46+U46+V46+W46+X46 -> 473
C47: Kelli VanLoenen Write-In | D47: Rep | E47: 3 | F47: 3 | G47: 5 | H47: 4 | I47: 4 | J47: 14 | K47: 42 | L47: 17 | M47: 4 | N47: 17 | O47: Kelli VanLoenen Write-In | P47: Rep | Q47: 2 | R47: 1 | S47: 12 | T47: 0 | U47: 1 | V47: 5 | W47: 16 | X47: 6 | Y47: =E47+F47+G47+H47+I47+J47+K47+L47+M47+N47+Q47+R47+S47+T47+U47+V47+W47+X47 -> 156
B48: COUNTY ATTORNEY | O48: COUNTY ATTORNEY
C49: Michael Abbott | D49: Rep | E49: 10 | F49: 31 | G49: 21 | H49: 15 | I49: 8 | J49: 25 | K49: 192 | L49: 52 | M49: 2 | N49: 25 | O49: Michael Abbott | P49: Rep | Q49: 20 | R49: 3 | S49: 34 | T49: 12 | U49: 12 | V49: 6 | W49: 48 | X49: 48 | Y49: =E49+F49+G49+H49+I49+J49+K49+L49+M49+N49+Q49+R49+S49+T49+U49+V49+W49+X49 -> 564
B50: COUNTY SHERIFF | O50: COUNTY SHERIFF
...

Sheet ELECTION DAY
B1: November 5th, 2024
B2: ELECTION DAY TOTALS
B3: NAME OF OFFICE | C3: NAME OF PERSON VOTED FOR | D3: PARTY | E3: ALLODIUM | F3: BRYANT | G3: GETTYSBURG | H3: GRAHAM | I3: HAPPPY | J3: HILL CITY #1 | K3: HILL CITY #2 | L3: HILL CITY #3 | M3: HILL CITY TWP #71 | N3: HILL CITY TWP #72 | O3: NAME OF PERSON VOTED FOR | P3: PARTY | Q3: HILL CITY TWP #73 | R3: INDIANA | S3: MILLBROOK | T3: MORLAN | U3: NICODEMUS | V3: PIONEER | W3: SOLOMON | X3: WILDHORSE | Y3: TOTAL
B4: PRESIDENT AND VICE PRESIDENT | O4: PRESIDENT AND VICE PRESIDENT
C5: Trump/Vance | D5: Rep. | E5: 10 | F5: 16 | G5: 16 | H5: 18 | I5: 15 | J5: 46 | K5: 78 | L5: 59 | M5: 2 | N5: 15 | O5: Trump/Vance | P5: Rep. | Q5: 9 | R5: 12 | S5: 31 | T5: 17 | U5: 6 | V5: 6 | W5: 30 | X5: 48 | Y5: =SUM(E5:X5) -> 434
C6: Harris/Walz | D6: Dem. | E6: 0 | F6: 2 | G6: 4 | H6: 0 | I6: 0 | J6: 9 | K6: 13 | L6: 14 | M6: 0 | N6: 3 | O6: Harris/Walz | P6: Dem. | Q6: 1 | R6: 1 | S6: 2 | T6: 0 | U6: 2 | V6: 0 | W6: 3 | X6: 5 | Y6: =SUM(E6:X6) -> 59
C7: Kennedy Jr./Shanahan | D7: Indep. | E7: 0 | F7: 0 | G7: 0 | H7: 0 | I7: 0 | J7: 1 | K7: 3 | L7: 0 | M7: 0 | N7: 0 | O7: Kennedy Jr./Shanahan | P7: Indep. | Q7: 0 | R7: 0 | S7: 0 | T7: 0 | U7: 0 | V7: 0 | W7: 0 | X7: 0 | Y7: =SUM(E7:X7) -> 4
C8: Oliver/ ter Maat | D8: Lib. | E8: 0 | F8: 0 | G8: 0 | H8: 0 | I8: 0 | J8: 0 | K8: 1 | L8: 0 | M8: 0 | N8: 0 | O8: Oliver/ ter Maat | P8: Lib. | Q8: 0 | R8: 0 | S8: 0 | T8: 0 | U8: 0 | V8: 0 | W8: 0 | X8: 0 | Y8: =SUM(E8:X8) -> 1
B9: UNITED STATES REPRESENTATIVE 1ST DISTRICT | O9: UNITED STATES REPRESENTATIVE 1ST DISTRICT
C10: Paul Buskirk | D10: Dem. | E10: 0 | F10: 2 | G10: 2 | H10: 0 | I10: 0 | J10: 6 | K10: 11 | L10: 8 | M10: 0 | N10: 4 | O10: Paul Buskirk | P10: Dem. | Q10: 0 | R10: 0 | S10: 2 | T10: 0 | U10: 2 | V10: 0 | W10: 2 | X10: 6 | Y10: =SUM(E10:X10) -> 45
C11: Tracey Mann | D11: Rep. | E11: 10 | F11: 16 | G11: 17 | H11: 17 | I11: 15 | J11: 50 | K11: 79 | L11: 61 | M11: 2 | N11: 14 | O11: Tracey Mann | P11: Rep. | Q11: 10 | R11: 13 | S11: 31 | T11: 16 | U11: 6 | V11: 6 | W11: 30 | X11: 46 | Y11: =SUM(E11:X11) -> 439
B13: STATE SENATOR 40TH DISTRICT | O13: STATE SENATOR 40TH DISTRICT
C14: Richard (Rick) Billinger | D14: Rep. | E14: 10 | F14: 16 | G14: 19 | H14: 18 | I14: 15 | J14: 49 | K14: 81 | L14: 64 | M14: 1 | N14: 18 | O14: Richard (Rick) Billinger | P14: Rep. | Q14: 10 | R14: 13 | S14: 30 | T14: 17 | U14: 6 | V14: 6 | W14: 28 | X14: 49 | Y14: =SUM(E14:X14) -> 450
B15: STATE REPRESENTATIVE 110TH DISTRICT | O15: STATE REPRESENTATIVE 110TH DISTRICT
C16: ellace Henderson | D16: Dem. | E16: 0 | F16: 2 | G16: 2 | H16: 0 | I16: 0 | J16: 8 | K16: 11 | L16: 11 | M16: 0 | N16: 5 | O16: ellace Henderson | P16: Dem. | Q16: 1 | R16: 1 | S16: 4 | T16: 0 | U16: 3 | V16: 0 | W16: 2 | X16: 7 | Y16: =SUM(E16:X16) -> 57
C17: Ken Rahjes | D17: Rep. | E17: 10 | F17: 12 | G17: 18 | H17: 17 | I17: 15 | J17: 46 | K17: 69 | L17: 59 | M17: 1 | N17: 12 | O17: Ken Rahjes | P17: Rep. | Q17: 9 | R17: 12 | S17: 27 | T17: 17 | U17: 5 | V17: 6 | W17: 30 | X17: 45 | Y17: =SUM(E17:X17) -> 410
B18: DISTRICT COURT JUDGE 17TH DISTRICT 1ST DIVISION | O18: DISTRICT COURT JUDGE 17TH DISTRICT 1ST DIVISION
C19: Jesse A. Thompson | D19: Rep. | E19: 10 | F19: 11 | G19: 19 | H19: 17 | I19: 15 | J19: 47 | K19: 83 | L19: 66 | M19: 2 | N19: 17 | O19: Jesse A. Thompson | P19: Rep. | Q19: 10 | R19: 13 | S19: 31 | T19: 14 | U19: 7 | V19: 7 | W19: 29 | X19: 48 | Y19: =SUM(E19:X19) -> 446
B21: DISTRICT COURT JUDGE 17TH DISTRICT 2ND DIVISION | O21: DISTRICT COURT JUDGE 17TH DISTRICT 2ND DIVISION
C22: Paula D. Hofaker | D22: Rep. | E22: 10 | F22: 11 | G22: 19 | H22: 16 | I22: 15 | J22: 45 | K22: 79 | L22: 60 | M22: 1 | N22: 17 | O22: Paula D. Hofaker | P22: Rep. | Q22: 8 | R22: 13 | S22: 29 | T22: 16 | U22: 6 | V22: 5 | W22: 28 | X22: 48 | Y22: =SUM(E22:X22) -> 426
B23: DISTRICT MAGISTRATE JUDGE 17TH DISTRICT 1ST POSITION | O23: COMMISSIONER OF INSURANCE
C24: Morgan Nutting | D24: Rep. | E24: 10 | F24: 10 | G24: 19 | H24: 18 | I24: 15 | J24: 46 | K24: 81 | L24: 67 | M24: 1 | N24: 15 | O24: Morgan Nutting | P24: Rep. | Q24: 10 | R24: 13 | S24: 26 | T24: 16 | U24: 5 | V24: 6 | W24: 28 | X24: 50 | Y24: =SUM(E24:X24) -> 436
B33: NAME OF OFFICE | C33: NAME OF PERSON VOTED FOR | D33: PARTY | E33: ALLODIUM | F33: BRYANT | G33: GETTYSBURG | H33: GRAHAM | I33: HAPPPY | J33: HILL CITY #1 | K33: HILL CITY #2 | L33: HILL CITY #3 | M33: HILL CITY TWP #71 | N33: HILL CITY TWP #72 | O33: NAME OF PERSON VOTED FOR | P33: PARTY | Q33: HILL CITY TWP #73 | R33: INDIANA | S33: MILLBROOK | T33: MORLAN | U33: NICODEMUS | V33: PIONEER | W33: SOLOMON | X33: WILDHORSE | Y33: TOTAL
B34: COUNTY COMMISSIONER 2ND DISTRICT | O34: COUNTY COMMISSIONER 2ND DISTRICT
C35: Jason Nelson | D35: Rep | E35: 0 | F35: 0 | G35: 0 | H35: 15 | I35: 0 | J35: 0 | K35: 70 | L35: 0 | M35: 0 | N35: 13 | O35: Jason Nelson | P35: Rep | Q35: 0 | R35: 0 | S35: 0 | T35: 0 | U35: 5 | V35: 7 | W35: 0 | X35: 0 | Y35: =E35+F35+G35+H35+I35+J35+K35+L35+M35+N35+Q35+R35+S35+T35+U35+V35+W35+X35 -> 110
Y36: =E36+F36+G36+H36+I36+J36+K36+L36+M36+N36+Q36+R36+S36+T36+U36+V36+W36+X36 -> 0
B37: COUNTY COMMISSIONER 3RD DISTRICT | O37: COUNTY COMMISSIONER 3RD DISTRICT
C38: Dan Irby | D38: Rep | E38: 0 | F38: 0 | G38: 0 | H38: 0 | I38: 14 | J38: 0 | K38: 0 | L38: 60 | M38: 0 | N38: 0 | O38: Dan Irby | P38: Rep | Q38: 10 | R38: 0 | S38: 26 | T38: 16 | U38: 0 | V38: 0 | W38: 0 | X38: 44 | Y38: =E38+F38+G38+H38+I38+J38+K38+L38+M38+N38+Q38+R38+S38+T38+U38+V38+W38+X38 -> 170
Y39: =E39+F39+G39+H39+I39+J39+K39+L39+M39+N39+Q39+R39+S39+T39+U39+V39+W39+X39 -> 0
B40: COUNTY CLERK | O40: COUNTY CLERK
C41: Kendra Robinson | D41: Rep. | E41: 10 | F41: 13 | G41: 19 | H41: 15 | I41: 15 | J41: 46 | K41: 78 | L41: 63 | M41: 2 | N41: 16 | O41: Kendra Robinson | P41: Rep. | Q41: 9 | R41: 13 | S41: 26 | T41: 17 | U41: 7 | V41: 7 | W41: 30 | X41: 45 | Y41: =E41+F41+G41+H41+I41+J41+K41+L41+M41+N41+Q41+R41+S41+T41+U41+V41+W41+X41 -> 431
B42: COUNTY TREASURER | O42: COUNTY TREASURER
C43: Jerilyn Keith | D43: Rep | E43: 10 | F43: 15 | G43: 19 | H43: 16 | I43: 15 | J43: 49 | K43: 84 | L43: 64 | M43: 2 | N43: 17 | O43: Jerilyn Keith | P43: Rep | Q43: 10 | R43: 13 | S43: 28 | T43: 17 | U43: 6 | V43: 7 | W43: 29 | X43: 48 | Y43: =E43+F43+G43+H43+I43+J43+K43+L43+M43+N43+Q43+R43+S43+T43+U43+V43+W43+X43 -> 449
Y44: =E44+F44+G44+H44+I44+J44+K44+L44+M44+N44+Q44+R44+S44+T44+U44+V44+W44+X44 -> 0
B45: COUNTY REGISTER OF DEEDS | O45: COUNTY REGISTER OF DEEDS
C46: Dani Roeder | D46: Rep | E46: 8 | F46: 12 | G46: 11 | H46: 11 | I46: 13 | J46: 28 | K46: 63 | L46: 44 | M46: 0 | N46: 9 | O46: Dani Roeder | P46: Rep | Q46: 6 | R46: 10 | S46: 17 | T46: 15 | U46: 5 | V46: 1 | W46: 22 | X46: 41 | Y46: =E46+F46+G46+H46+I46+J46+K46+L46+M46+N46+Q46+R46+S46+T46+U46+V46+W46+X46 -> 316
C47: Kelli VanLoenen Write-In | D47: Rep | E47: 2 | F47: 0 | G47: 8 | H47: 7 | I47: 0 | J47: 19 | K47: 44 | L47: 22 | M47: 2 | N47: 5 | O47: Kelli VanLoenen Write-In | P47: Rep | Q47: 2 | R47: 3 | S47: 14 | T47: 2 | U47: 1 | V47: 4 | W47: 6 | X47: 12 | Y47: =E47+F47+G47+H47+I47+J47+K47+L47+M47+N47+Q47+R47+S47+T47+U47+V47+W47+X47 -> 153
B48: COUNTY ATTORNEY | O48: COUNTY ATTORNEY
C49: Michael Abbott | D49: Rep | E49: 10 | F49: 11 | G49: 19 | H49: 16 | I49: 15 | J49: 46 | K49: 77 | L49: 62 | M49: 1 | N49: 17 | O49: Michael Abbott | P49: Rep | Q49: 10 | R49: 13 | S49: 28 | T49: 16 | U49: 6 | V49: 5 | W49: 28 | X49: 48 | Y49: =E49+F49+G49+H49+I49+J49+K49+L49+M49+N49+Q49+R49+S49+T49+U49+V49+W49+X49 -> 428
B50: COUNTY SHERIFF | O50: COUNTY SHERIFF
...

Sheet ADVANCE & ELECTION DAY TOTAL
B1: November 5th, 2024
B2: TOTALS
B3: NAME OF OFFICE | C3: NAME OF PERSON VOTED FOR | D3: PARTY | E3: ALLODIUM | F3: BRYANT | G3: GETTYSBURG | H3: GRAHAM | I3: HAPPPY | J3: HILL CITY #1 | K3: HILL CITY #2 | L3: HILL CITY #3 | M3: HILL CITY TWP #71 | N3: HILL CITY TWP #72 | O3: NAME OF PERSON VOTED FOR | P3: PARTY | Q3: HILL CITY TWP #73 | R3: INDIANA | S3: MILLBROOK | T3: MORLAN | U3: NICODEMUS | V3: PIONEER | W3: SOLOMON | X3: WILDHORSE | Y3: TOTAL
B4: PRESIDENT AND VICE PRESIDENT | O4: PRESIDENT AND VICE PRESIDENT
C5: Trump/Vance | D5: Rep. | E5: =SUM('ADVANCE:ELECTION DAY'!E5) -> 20 | F5: =SUM('ADVANCE:ELECTION DAY'!F5) -> 47 | G5: =SUM('ADVANCE:ELECTION DAY'!G5) -> 37 | H5: =SUM('ADVANCE:ELECTION DAY'!H5) -> 29 | I5: =SUM('ADVANCE:ELECTION DAY'!I5) -> 22 | J5: =SUM('ADVANCE:ELECTION DAY'!J5) -> 70 | K5: =SUM('ADVANCE:ELECTION DAY'!K5) -> 267 | L5: =SUM('ADVANCE:ELECTION DAY'!L5) -> 116 | ... N5: =SUM('ADVANCE:ELECTION DAY'!N5) -> 37 | O5: Trump/Vance | P5: Rep. | Q5: =SUM('ADVANCE:ELECTION DAY'!Q5) -> 29 | R5: =SUM('ADVANCE:ELECTION DAY'!R5) -> 15 | S5: =SUM('ADVANCE:ELECTION DAY'!S5) -> 62 | T5: =SUM('ADVANCE:ELECTION DAY'!T5) -> 30 | U5: =SUM('ADVANCE:ELECTION DAY'!U5) -> 12 | V5: =SUM('ADVANCE:ELECTION DAY'!V5) -> 16 | W5: =SUM('ADVANCE:ELECTION DAY'!W5) -> 76 | X5: =SUM('ADVANCE:ELECTION DAY'!X5) -> 92 | Y5: =SUM(E5:X5) -> 983
C6: Harris/Walz | D6: Dem. | E6: =SUM('ADVANCE:ELECTION DAY'!E6) -> 0 | F6: =SUM('ADVANCE:ELECTION DAY'!F6) -> 5 | G6: =SUM('ADVANCE:ELECTION DAY'!G6) -> 5 | H6: =SUM('ADVANCE:ELECTION DAY'!H6) -> 7 | I6: =SUM('ADVANCE:ELECTION DAY'!I6) -> 8 | J6: =SUM('ADVANCE:ELECTION DAY'!J6) -> 15 | K6: =SUM('ADVANCE:ELECTION DAY'!K6) -> 70 | L6: =SUM('ADVANCE:ELECTION DAY'!L6) -> 28 | ... N6: =SUM('ADVANCE:ELECTION DAY'!N6) -> 7 | O6: Harris/Walz | P6: Dem. | Q6: =SUM('ADVANCE:ELECTION DAY'!Q6) -> 3 | R6: =SUM('ADVANCE:ELECTION DAY'!R6) -> 1 | S6: =SUM('ADVANCE:ELECTION DAY'!S6) -> 8 | T6: =SUM('ADVANCE:ELECTION DAY'!T6) -> 1 | U6: =SUM('ADVANCE:ELECTION DAY'!U6) -> 9 | V6: =SUM('ADVANCE:ELECTION DAY'!V6) -> 0 | W6: =SUM('ADVANCE:ELECTION DAY'!W6) -> 9 | X6: =SUM('ADVANCE:ELECTION DAY'!X6) -> 16 | Y6: =SUM(E6:X6) -> 192
C7: Kennedy Jr./Shanahan | D7: Indep. | E7: =SUM('ADVANCE:ELECTION DAY'!E7) -> 0 | F7: =SUM('ADVANCE:ELECTION DAY'!F7) -> 0 | G7: =SUM('ADVANCE:ELECTION DAY'!G7) -> 1 | H7: =SUM('ADVANCE:ELECTION DAY'!H7) -> 0 | I7: =SUM('ADVANCE:ELECTION DAY'!I7) -> 0 | J7: =SUM('ADVANCE:ELECTION DAY'!J7) -> 3 | K7: =SUM('ADVANCE:ELECTION DAY'!K7) -> 11 | L7: =SUM('ADVANCE:ELECTION DAY'!L7) -> 1 | ... N7: =SUM('ADVANCE:ELECTION DAY'!N7) -> 0 | O7: Kennedy Jr./Shanahan | P7: Indep. | Q7: =SUM('ADVANCE:ELECTION DAY'!Q7) -> 0 | R7: =SUM('ADVANCE:ELECTION DAY'!R7) -> 1 | S7: =SUM('ADVANCE:ELECTION DAY'!S7) -> 0 | T7: =SUM('ADVANCE:ELECTION DAY'!T7) -> 0 | U7: =SUM('ADVANCE:ELECTION DAY'!U7) -> 0 | V7: =SUM('ADVANCE:ELECTION DAY'!V7) -> 0 | W7: =SUM('ADVANCE:ELECTION DAY'!W7) -> 1 | X7: =SUM('ADVANCE:ELECTION DAY'!X7) -> 0 | Y7: =SUM(E7:X7) -> 18
C8: Oliver/ ter Maat | D8: Lib. | E8: =SUM('ADVANCE:ELECTION DAY'!E8) -> 0 | F8: =SUM('ADVANCE:ELECTION DAY'!F8) -> 0 | G8: =SUM('ADVANCE:ELECTION DAY'!G8) -> 0 | H8: =SUM('ADVANCE:ELECTION DAY'!H8) -> 0 | I8: =SUM('ADVANCE:ELECTION DAY'!I8) -> 0 | J8: =SUM('ADVANCE:ELECTION DAY'!J8) -> 0 | K8: =SUM('ADVANCE:ELECTION DAY'!K8) -> 1 | L8: =SUM('ADVANCE:ELECTION DAY'!L8) -> 0 | ... N8: =SUM('ADVANCE:ELECTION DAY'!N8) -> 0 | O8: Oliver/ ter Maat | P8: Lib. | Q8: =SUM('ADVANCE:ELECTION DAY'!Q8) -> 0 | R8: =SUM('ADVANCE:ELECTION DAY'!R8) -> 0 | S8: =SUM('ADVANCE:ELECTION DAY'!S8) -> 0 | T8: =SUM('ADVANCE:ELECTION DAY'!T8) -> 0 | U8: =SUM('ADVANCE:ELECTION DAY'!U8) -> 0 | V8: =SUM('ADVANCE:ELECTION DAY'!V8) -> 0 | W8: =SUM('ADVANCE:ELECTION DAY'!W8) -> 0 | X8: =SUM('ADVANCE:ELECTION DAY'!X8) -> 0 | Y8: =SUM(E8:X8) -> 1
B9: UNITED STATES REPRESENTATIVE 1ST DISTRICT | O9: UNITED STATES REPRESENTATIVE 1ST DISTRICT
C10: Paul Buskirk | D10: Dem. | E10: =SUM('ADVANCE:ELECTION DAY'!E10) -> 0 | F10: =SUM('ADVANCE:ELECTION DAY'!F10) -> 4 | G10: =SUM('ADVANCE:ELECTION DAY'!G10) -> 4 | H10: =SUM('ADVANCE:ELECTION DAY'!H10) -> 7 | I10: =SUM('ADVANCE:ELECTION DAY'!I10) -> 6 | J10: =SUM('ADVANCE:ELECTION DAY'!J10) -> 10 | K10: =SUM('ADVANCE:ELECTION DAY'!K10) -> 53 | L10: =SUM('ADVANCE:ELECTION DAY'!L10) -> 19 | ... N10: =SUM('ADVANCE:ELECTION DAY'!N10) -> 4 | O10: Paul Buskirk | P10: Dem. | Q10: =SUM('ADVANCE:ELECTION DAY'!Q10) -> 0 | R10: =SUM('ADVANCE:ELECTION DAY'!R10) -> 0 | S10: =SUM('ADVANCE:ELECTION DAY'!S10) -> 6 | T10: =SUM('ADVANCE:ELECTION DAY'!T10) -> 0 | U10: =SUM('ADVANCE:ELECTION DAY'!U10) -> 8 | V10: =SUM('ADVANCE:ELECTION DAY'!V10) -> 0 | W10: =SUM('ADVANCE:ELECTION DAY'!W10) -> 6 | X10: =SUM('ADVANCE:ELECTION DAY'!X10) -> 13 | Y10: =SUM(E10:X10) -> 140
C11: Tracey Mann | D11: Rep. | E11: =SUM('ADVANCE:ELECTION DAY'!E11) -> 20 | F11: =SUM('ADVANCE:ELECTION DAY'!F11) -> 48 | G11: =SUM('ADVANCE:ELECTION DAY'!G11) -> 39 | H11: =SUM('ADVANCE:ELECTION DAY'!H11) -> 27 | I11: =SUM('ADVANCE:ELECTION DAY'!I11) -> 24 | J11: =SUM('ADVANCE:ELECTION DAY'!J11) -> 75 | K11: =SUM('ADVANCE:ELECTION DAY'!K11) -> 265 | L11: =SUM('ADVANCE:ELECTION DAY'!L11) -> 117 | ... N11: =SUM('ADVANCE:ELECTION DAY'!N11) -> 41 | O11: Tracey Mann | P11: Rep. | Q11: =SUM('ADVANCE:ELECTION DAY'!Q11) -> 32 | R11: =SUM('ADVANCE:ELECTION DAY'!R11) -> 17 | S11: =SUM('ADVANCE:ELECTION DAY'!S11) -> 63 | T11: =SUM('ADVANCE:ELECTION DAY'!T11) -> 30 | U11: =SUM('ADVANCE:ELECTION DAY'!U11) -> 13 | V11: =SUM('ADVANCE:ELECTION DAY'!V11) -> 14 | W11: =SUM('ADVANCE:ELECTION DAY'!W11) -> 79 | X11: =SUM('ADVANCE:ELECTION DAY'!X11) -> 94 | Y11: =SUM(E11:X11) -> 1004
E12: =SUM('ADVANCE:ELECTION DAY'!E12) -> 0 | F12: =SUM('ADVANCE:ELECTION DAY'!F12) -> 0 | G12: =SUM('ADVANCE:ELECTION DAY'!G12) -> 0 | H12: =SUM('ADVANCE:ELECTION DAY'!H12) -> 0 | I12: =SUM('ADVANCE:ELECTION DAY'!I12) -> 0 | J12: =SUM('ADVANCE:ELECTION DAY'!J12) -> 0 | K12: =SUM('ADVANCE:ELECTION DAY'!K12) -> 0 | L12: =SUM('ADVANCE:ELECTION DAY'!L12) -> 0 | ... N12: =SUM('ADVANCE:ELECTION DAY'!N12) -> 0 | Q12: =SUM('ADVANCE:ELECTION DAY'!Q12) -> 0 | R12: =SUM('ADVANCE:ELECTION DAY'!R12) -> 0 | S12: =SUM('ADVANCE:ELECTION DAY'!S12) -> 0 | T12: =SUM('ADVANCE:ELECTION DAY'!T12) -> 0 | U12: =SUM('ADVANCE:ELECTION DAY'!U12) -> 0 | V12: =SUM('ADVANCE:ELECTION DAY'!V12) -> 0 | W12: =SUM('ADVANCE:ELECTION DAY'!W12) -> 0 | X12: =SUM('ADVANCE:ELECTION DAY'!X12) -> 0
B13: STATE SENATOR 40TH DISTRICT | O13: STATE SENATOR 40TH DISTRICT
C14: Richard (Rick) Billinger | D14: Rep. | E14: =SUM('ADVANCE:ELECTION DAY'!E14) -> 20 | F14: =SUM('ADVANCE:ELECTION DAY'!F14) -> 48 | G14: =SUM('ADVANCE:ELECTION DAY'!G14) -> 41 | H14: =SUM('ADVANCE:ELECTION DAY'!H14) -> 31 | I14: =SUM('ADVANCE:ELECTION DAY'!I14) -> 28 | J14: =SUM('ADVANCE:ELECTION DAY'!J14) -> 72 | K14: =SUM('ADVANCE:ELECTION DAY'!K14) -> 285 | L14: =SUM('ADVANCE:ELECTION DAY'!L14) -> 119 | ... N14: =SUM('ADVANCE:ELECTION DAY'!N14) -> 44 | O14: Richard (Rick) Billinger | P14: Rep. | Q14: =SUM('ADVANCE:ELECTION DAY'!Q14) -> 32 | R14: =SUM('ADVANCE:ELECTION DAY'!R14) -> 16 | S14: =SUM('ADVANCE:ELECTION DAY'!S14) -> 66 | T14: =SUM('ADVANCE:ELECTION DAY'!T14) -> 31 | U14: =SUM('ADVANCE:ELECTION DAY'!U14) -> 18 | V14: =SUM('ADVANCE:ELECTION DAY'!V14) -> 15 | W14: =SUM('ADVANCE:ELECTION DAY'!W14) -> 76 | X14: =SUM('ADVANCE:ELECTION DAY'!X14) -> 98 | Y14: =SUM(E14:X14) -> 1045
B15: STATE REPRESENTATIVE 110TH DISTRICT | O15: STATE REPRESENTATIVE 110TH DISTRICT
C16: ellace Henderson | D16: Dem. | E16: =SUM('ADVANCE:ELECTION DAY'!E16) -> 0 | F16: =SUM('ADVANCE:ELECTION DAY'!F16) -> 7 | G16: =SUM('ADVANCE:ELECTION DAY'!G16) -> 5 | H16: =SUM('ADVANCE:ELECTION DAY'!H16) -> 6 | I16: =SUM('ADVANCE:ELECTION DAY'!I16) -> 7 | J16: =SUM('ADVANCE:ELECTION DAY'!J16) -> 16 | K16: =SUM('ADVANCE:ELECTION DAY'!K16) -> 58 | L16: =SUM('ADVANCE:ELECTION DAY'!L16) -> 24 | ... N16: =SUM('ADVANCE:ELECTION DAY'!N16) -> 5 | O16: ellace Henderson | P16: Dem. | Q16: =SUM('ADVANCE:ELECTION DAY'!Q16) -> 1 | R16: =SUM('ADVANCE:ELECTION DAY'!R16) -> 2 | S16: =SUM('ADVANCE:ELECTION DAY'!S16) -> 9 | T16: =SUM('ADVANCE:ELECTION DAY'!T16) -> 0 | U16: =SUM('ADVANCE:ELECTION DAY'!U16) -> 9 | V16: =SUM('ADVANCE:ELECTION DAY'!V16) -> 1 | W16: =SUM('ADVANCE:ELECTION DAY'!W16) -> 8 | X16: =SUM('ADVANCE:ELECTION DAY'!X16) -> 13 | Y16: =SUM(E16:X16) -> 171
C17: Ken Rahjes | D17: Rep. | E17: =SUM('ADVANCE:ELECTION DAY'!E17) -> 20 | F17: =SUM('ADVANCE:ELECTION DAY'!F17) -> 38 | G17: =SUM('ADVANCE:ELECTION DAY'!G17) -> 39 | H17: =SUM('ADVANCE:ELECTION DAY'!H17) -> 28 | I17: =SUM('ADVANCE:ELECTION DAY'!I17) -> 23 | J17: =SUM('ADVANCE:ELECTION DAY'!J17) -> 67 | K17: =SUM('ADVANCE:ELECTION DAY'!K17) -> 244 | L17: =SUM('ADVANCE:ELECTION DAY'!L17) -> 105 | ... N17: =SUM('ADVANCE:ELECTION DAY'!N17) -> 39 | O17: Ken Rahjes | P17: Rep. | Q17: =SUM('ADVANCE:ELECTION DAY'!Q17) -> 30 | R17: =SUM('ADVANCE:ELECTION DAY'!R17) -> 15 | S17: =SUM('ADVANCE:ELECTION DAY'!S17) -> 58 | T17: =SUM('ADVANCE:ELECTION DAY'!T17) -> 31 | U17: =SUM('ADVANCE:ELECTION DAY'!U17) -> 12 | V17: =SUM('ADVANCE:ELECTION DAY'!V17) -> 13 | W17: =SUM('ADVANCE:ELECTION DAY'!W17) -> 76 | X17: =SUM('ADVANCE:ELECTION DAY'!X17) -> 92 | Y17: =SUM(E17:X17) -> 935
B18: DISTRICT COURT JUDGE 17TH DISTRICT 1ST DIVISION | O18: DISTRICT COURT JUDGE 17TH DISTRICT 1ST DIVISION
C19: Jesse A. Thompson | D19: Rep. | E19: =SUM('ADVANCE:ELECTION DAY'!E19) -> 19 | F19: =SUM('ADVANCE:ELECTION DAY'!F19) -> 43 | G19: =SUM('ADVANCE:ELECTION DAY'!G19) -> 42 | H19: =SUM('ADVANCE:ELECTION DAY'!H19) -> 31 | I19: =SUM('ADVANCE:ELECTION DAY'!I19) -> 27 | J19: =SUM('ADVANCE:ELECTION DAY'!J19) -> 72 | K19: =SUM('ADVANCE:ELECTION DAY'!K19) -> 281 | L19: =SUM('ADVANCE:ELECTION DAY'!L19) -> 127 | ... N19: =SUM('ADVANCE:ELECTION DAY'!N19) -> 42 | O19: Jesse A. Thompson | P19: Rep. | Q19: =SUM('ADVANCE:ELECTION DAY'!Q19) -> 30 | R19: =SUM('ADVANCE:ELECTION DAY'!R19) -> 16 | S19: =SUM('ADVANCE:ELECTION DAY'!S19) -> 66 | T19: =SUM('ADVANCE:ELECTION DAY'!T19) -> 26 | U19: =SUM('ADVANCE:ELECTION DAY'!U19) -> 18 | V19: =SUM('ADVANCE:ELECTION DAY'!V19) -> 15 | W19: =SUM('ADVANCE:ELECTION DAY'!W19) -> 75 | X19: =SUM('ADVANCE:ELECTION DAY'!X19) -> 99 | Y19: =SUM(E19:X19) -> 1032
E20: =SUM('ADVANCE:ELECTION DAY'!E20) -> 0 | F20: =SUM('ADVANCE:ELECTION DAY'!F20) -> 0 | G20: =SUM('ADVANCE:ELECTION DAY'!G20) -> 0 | H20: =SUM('ADVANCE:ELECTION DAY'!H20) -> 0 | I20: =SUM('ADVANCE:ELECTION DAY'!I20) -> 0 | J20: =SUM('ADVANCE:ELECTION DAY'!J20) -> 0 | K20: =SUM('ADVANCE:ELECTION DAY'!K20) -> 0 | L20: =SUM('ADVANCE:ELECTION DAY'!L20) -> 0 | ... N20: =SUM('ADVANCE:ELECTION DAY'!N20) -> 0 | Q20: =SUM('ADVANCE:ELECTION DAY'!Q20) -> 0 | R20: =SUM('ADVANCE:ELECTION DAY'!R20) -> 0 | S20: =SUM('ADVANCE:ELECTION DAY'!S20) -> 0 | T20: =SUM('ADVANCE:ELECTION DAY'!T20) -> 0 | U20: =SUM('ADVANCE:ELECTION DAY'!U20) -> 0 | V20: =SUM('ADVANCE:ELECTION DAY'!V20) -> 0 | W20: =SUM('ADVANCE:ELECTION DAY'!W20) -> 0 | X20: =SUM('ADVANCE:ELECTION DAY'!X20) -> 0
B21: DISTRICT COURT JUDGE 17TH DISTRICT 2ND DIVISION | O21: DISTRICT COURT JUDGE 17TH DISTRICT 2ND DIVISION
C22: Paula D. Hofaker | D22: Rep. | E22: =SUM('ADVANCE:ELECTION DAY'!E22) -> 20 | F22: =SUM('ADVANCE:ELECTION DAY'!F22) -> 42 | G22: =SUM('ADVANCE:ELECTION DAY'!G22) -> 40 | H22: =SUM('ADVANCE:ELECTION DAY'!H22) -> 30 | I22: =SUM('ADVANCE:ELECTION DAY'!I22) -> 25 | J22: =SUM('ADVANCE:ELECTION DAY'!J22) -> 67 | K22: =SUM('ADVANCE:ELECTION DAY'!K22) -> 268 | L22: =SUM('ADVANCE:ELECTION DAY'!L22) -> 116 | ... N22: =SUM('ADVANCE:ELECTION DAY'!N22) -> 43 | O22: Paula D. Hofaker | P22: Rep. | Q22: =SUM('ADVANCE:ELECTION DAY'!Q22) -> 29 | R22: =SUM('ADVANCE:ELECTION DAY'!R22) -> 17 | S22: =SUM('ADVANCE:ELECTION DAY'!S22) -> 64 | T22: =SUM('ADVANCE:ELECTION DAY'!T22) -> 29 | U22: =SUM('ADVANCE:ELECTION DAY'!U22) -> 17 | V22: =SUM('ADVANCE:ELECTION DAY'!V22) -> 11 | W22: =SUM('ADVANCE:ELECTION DAY'!W22) -> 74 | X22: =SUM('ADVANCE:ELECTION DAY'!X22) -> 98 | Y22: =SUM(E22:X22) -> 994
B23: DISTRICT MAGISTRATE JUDGE 17TH DISTRICT 1ST POSITION | O23: DISTRICT MAGISTRATE JUDGE 17TH DISTRICT 1ST POSITION
C24: Morgan Nutting | D24: Rep. | E24: =SUM('ADVANCE:ELECTION DAY'!E24) -> 19 | F24: =SUM('ADVANCE:ELECTION DAY'!F24) -> 41 | G24: =SUM('ADVANCE:ELECTION DAY'!G24) -> 41 | H24: =SUM('ADVANCE:ELECTION DAY'!H24) -> 31 | I24: =SUM('ADVANCE:ELECTION DAY'!I24) -> 25 | J24: =SUM('ADVANCE:ELECTION DAY'!J24) -> 74 | K24: =SUM('ADVANCE:ELECTION DAY'!K24) -> 289 | L24: =SUM('ADVANCE:ELECTION DAY'!L24) -> 130 | ... N24: =SUM('ADVANCE:ELECTION DAY'!N24) -> 38 | O24: Morgan Nutting | P24: Rep. | Q24: =SUM('ADVANCE:ELECTION DAY'!Q24) -> 30 | R24: =SUM('ADVANCE:ELECTION DAY'!R24) -> 16 | S24: =SUM('ADVANCE:ELECTION DAY'!S24) -> 58 | T24: =SUM('ADVANCE:ELECTION DAY'!T24) -> 26 | U24: =SUM('ADVANCE:ELECTION DAY'!U24) -> 15 | V24: =SUM('ADVANCE:ELECTION DAY'!V24) -> 15 | W24: =SUM('ADVANCE:ELECTION DAY'!W24) -> 74 | X24: =SUM('ADVANCE:ELECTION DAY'!X24) -> 99 | Y24: =SUM(E24:X24) -> 1026
B30: November 5th, 2024
B31: TOTALS
B33: NAME OF OFFICE | C33: NAME OF PERSON VOTED FOR | D33: PARTY | E33: ALLODIUM | F33: BRYANT | G33: GETTYSBURG | H33: GRAHAM | I33: HAPPPY | J33: HILL CITY #1 | K33: HILL CITY #2 | L33: HILL CITY #3 | M33: HILL CITY TWP #71 | N33: HILL CITY TWP #72 | O33: NAME OF PERSON VOTED FOR | P33: PARTY | Q33: HILL CITY TWP #73 | R33: INDIANA | S33: MILLBROOK | T33: MORLAN | U33: NICODEMUS | V33: PIONEER | W33: SOLOMON | X33: WILDHORSE | Y33: TOTAL
B34: COUNTY COMMISSIONER 2ND DISTRICT | O34: COUNTY COMMISSIONER 2ND DISTRICT
C35: Jason Nelson | D35: Rep | E35: =SUM('ADVANCE:ELECTION DAY'!E35) -> 0 | F35: =SUM('ADVANCE:ELECTION DAY'!F35) -> 0 | G35: =SUM('ADVANCE:ELECTION DAY'!G35) -> 0 | H35: =SUM('ADVANCE:ELECTION DAY'!H35) -> 32 | I35: =SUM('ADVANCE:ELECTION DAY'!I35) -> 0 | J35: =SUM('ADVANCE:ELECTION DAY'!J35) -> 0 | K35: =SUM('ADVANCE:ELECTION DAY'!K35) -> 252 | L35: =SUM('ADVANCE:ELECTION DAY'!L35) -> 0 | ... N35: =SUM('ADVANCE:ELECTION DAY'!N35) -> 35 | O35: Jason Nelson | P35: Rep | Q35: =SUM('ADVANCE:ELECTION DAY'!Q35) -> 0 | R35: =SUM('ADVANCE:ELECTION DAY'!R35) -> 0 | S35: =SUM('ADVANCE:ELECTION DAY'!S35) -> 0 | T35: =SUM('ADVANCE:ELECTION DAY'!T35) -> 0 | U35: =SUM('ADVANCE:ELECTION DAY'!U35) -> 16 | V35: =SUM('ADVANCE:ELECTION DAY'!V35) -> 17 | W35: =SUM('ADVANCE:ELECTION DAY'!W35) -> 0 | X35: =SUM('ADVANCE:ELECTION DAY'!X35) -> 0 | Y35: =E35+F35+G35+H35+I35+J35+K35+L35+M35+N35+Q35+R35+S35+T35+U35+V35+W35+X35 -> 352
E36: =SUM('ADVANCE:ELECTION DAY'!E36) -> 0 | F36: =SUM('ADVANCE:ELECTION DAY'!F36) -> 0 | G36: =SUM('ADVANCE:ELECTION DAY'!G36) -> 0 | H36: =SUM('ADVANCE:ELECTION DAY'!H36) -> 0 | I36: =SUM('ADVANCE:ELECTION DAY'!I36) -> 0 | J36: =SUM('ADVANCE:ELECTION DAY'!J36) -> 0 | K36: =SUM('ADVANCE:ELECTION DAY'!K36) -> 0 | L36: =SUM('ADVANCE:ELECTION DAY'!L36) -> 0 | ... N36: =SUM('ADVANCE:ELECTION DAY'!N36) -> 0 | Q36: =SUM('ADVANCE:ELECTION DAY'!Q36) -> 0 | R36: =SUM('ADVANCE:ELECTION DAY'!R36) -> 0 | S36: =SUM('ADVANCE:ELECTION DAY'!S36) -> 0 | T36: =SUM('ADVANCE:ELECTION DAY'!T36) -> 0 | U36: =SUM('ADVANCE:ELECTION DAY'!U36) -> 0 | V36: =SUM('ADVANCE:ELECTION DAY'!V36) -> 0 | W36: =SUM('ADVANCE:ELECTION DAY'!W36) -> 0 | X36: =SUM('ADVANCE:ELECTION DAY'!X36) -> 0 | Y36: =E36+F36+G36+H36+I36+J36+K36+L36+M36+N36+Q36+R36+S36+T36+U36+V36+W36+X36 -> 0
B37: COUNTY COMMISSIONER 3RD DISTRICT | O37: COUNTY COMMISSIONER 3RD DISTRICT
C38: Dan Irby | D38: Rep | E38: =SUM('ADVANCE:ELECTION DAY'!E38) -> 0 | F38: =SUM('ADVANCE:ELECTION DAY'!F38) -> 0 | G38: =SUM('ADVANCE:ELECTION DAY'!G38) -> 0 | H38: =SUM('ADVANCE:ELECTION DAY'!H38) -> 0 | I38: =SUM('ADVANCE:ELECTION DAY'!I38) -> 30 | J38: =SUM('ADVANCE:ELECTION DAY'!J38) -> 0 | K38: =SUM('ADVANCE:ELECTION DAY'!K38) -> 0 | L38: =SUM('ADVANCE:ELECTION DAY'!L38) -> 122 | ... N38: =SUM('ADVANCE:ELECTION DAY'!N38) -> 0 | O38: Dan Irby | P38: Rep | Q38: =SUM('ADVANCE:ELECTION DAY'!Q38) -> 29 | R38: =SUM('ADVANCE:ELECTION DAY'!R38) -> 0 | S38: =SUM('ADVANCE:ELECTION DAY'!S38) -> 60 | T38: =SUM('ADVANCE:ELECTION DAY'!T38) -> 30 | U38: =SUM('ADVANCE:ELECTION DAY'!U38) -> 0 | V38: =SUM('ADVANCE:ELECTION DAY'!V38) -> 0 | W38: =SUM('ADVANCE:ELECTION DAY'!W38) -> 0 | X38: =SUM('ADVANCE:ELECTION DAY'!X38) -> 96 | Y38: =E38+F38+G38+H38+I38+J38+K38+L38+M38+N38+Q38+R38+S38+T38+U38+V38+W38+X38 -> 367
E39: =SUM('ADVANCE:ELECTION DAY'!E39) -> 0 | F39: =SUM('ADVANCE:ELECTION DAY'!F39) -> 0 | G39: =SUM('ADVANCE:ELECTION DAY'!G39) -> 0 | H39: =SUM('ADVANCE:ELECTION DAY'!H39) -> 0 | I39: =SUM('ADVANCE:ELECTION DAY'!I39) -> 0 | J39: =SUM('ADVANCE:ELECTION DAY'!J39) -> 0 | K39: =SUM('ADVANCE:ELECTION DAY'!K39) -> 0 | L39: =SUM('ADVANCE:ELECTION DAY'!L39) -> 0 | ... N39: =SUM('ADVANCE:ELECTION DAY'!N39) -> 0 | Q39: =SUM('ADVANCE:ELECTION DAY'!Q39) -> 0 | R39: =SUM('ADVANCE:ELECTION DAY'!R39) -> 0 | S39: =SUM('ADVANCE:ELECTION DAY'!S39) -> 0 | T39: =SUM('ADVANCE:ELECTION DAY'!T39) -> 0 | U39: =SUM('ADVANCE:ELECTION DAY'!U39) -> 0 | V39: =SUM('ADVANCE:ELECTION DAY'!V39) -> 0 | W39: =SUM('ADVANCE:ELECTION DAY'!W39) -> 0 | X39: =SUM('ADVANCE:ELECTION DAY'!X39) -> 0 | Y39: =E39+F39+G39+H39+I39+J39+K39+L39+M39+N39+Q39+R39+S39+T39+U39+V39+W39+X39 -> 0
B40: COUNTY CLERK | O40: COUNTY CLERK
C41: Kendra Robinson | D41: Rep. | E41: =SUM('ADVANCE:ELECTION DAY'!E41) -> 20 | F41: =SUM('ADVANCE:ELECTION DAY'!F41) -> 46 | G41: =SUM('ADVANCE:ELECTION DAY'!G41) -> 40 | H41: =SUM('ADVANCE:ELECTION DAY'!H41) -> 28 | I41: =SUM('ADVANCE:ELECTION DAY'!I41) -> 29 | J41: =SUM('ADVANCE:ELECTION DAY'!J41) -> 74 | K41: =SUM('ADVANCE:ELECTION DAY'!K41) -> 286 | L41: =SUM('ADVANCE:ELECTION DAY'!L41) -> 117 | ... N41: =SUM('ADVANCE:ELECTION DAY'!N41) -> 43 | O41: Kendra Robinson | P41: Rep. | Q41: =SUM('ADVANCE:ELECTION DAY'!Q41) -> 30 | R41: =SUM('ADVANCE:ELECTION DAY'!R41) -> 16 | S41: =SUM('ADVANCE:ELECTION DAY'!S41) -> 62 | T41: =SUM('ADVANCE:ELECTION DAY'!T41) -> 30 | U41: =SUM('ADVANCE:ELECTION DAY'!U41) -> 18 | V41: =SUM('ADVANCE:ELECTION DAY'!V41) -> 15 | W41: =SUM('ADVANCE:ELECTION DAY'!W41) -> 80 | X41: =SUM('ADVANCE:ELECTION DAY'!X41) -> 99 | Y41: =E41+F41+G41+H41+I41+J41+K41+L41+M41+N41+Q41+R41+S41+T41+U41+V41+W41+X41 -> 1037
B42: COUNTY TREASURER | O42: COUNTY TREASURER
C43: Jerilyn Keith | D43: Rep | E43: =SUM('ADVANCE:ELECTION DAY'!E43) -> 20 | F43: =SUM('ADVANCE:ELECTION DAY'!F43) -> 46 | G43: =SUM('ADVANCE:ELECTION DAY'!G43) -> 42 | H43: =SUM('ADVANCE:ELECTION DAY'!H43) -> 32 | I43: =SUM('ADVANCE:ELECTION DAY'!I43) -> 29 | J43: =SUM('ADVANCE:ELECTION DAY'!J43) -> 76 | K43: =SUM('ADVANCE:ELECTION DAY'!K43) -> 295 | L43: =SUM('ADVANCE:ELECTION DAY'!L43) -> 125 | ... N43: =SUM('ADVANCE:ELECTION DAY'!N43) -> 44 | O43: Jerilyn Keith | P43: Rep | Q43: =SUM('ADVANCE:ELECTION DAY'!Q43) -> 29 | R43: =SUM('ADVANCE:ELECTION DAY'!R43) -> 17 | S43: =SUM('ADVANCE:ELECTION DAY'!S43) -> 65 | T43: =SUM('ADVANCE:ELECTION DAY'!T43) -> 30 | U43: =SUM('ADVANCE:ELECTION DAY'!U43) -> 18 | V43: =SUM('ADVANCE:ELECTION DAY'!V43) -> 16 | W43: =SUM('ADVANCE:ELECTION DAY'!W43) -> 77 | X43: =SUM('ADVANCE:ELECTION DAY'!X43) -> 100 | Y43: =E43+F43+G43+H43+I43+J43+K43+L43+M43+N43+Q43+R43+S43+T43+U43+V43+W43+X43 -> 1066
E44: =SUM('ADVANCE:ELECTION DAY'!E44) -> 0 | F44: =SUM('ADVANCE:ELECTION DAY'!F44) -> 0 | G44: =SUM('ADVANCE:ELECTION DAY'!G44) -> 0 | H44: =SUM('ADVANCE:ELECTION DAY'!H44) -> 0 | I44: =SUM('ADVANCE:ELECTION DAY'!I44) -> 0 | J44: =SUM('ADVANCE:ELECTION DAY'!J44) -> 0 | K44: =SUM('ADVANCE:ELECTION DAY'!K44) -> 0 | L44: =SUM('ADVANCE:ELECTION DAY'!L44) -> 0 | ... N44: =SUM('ADVANCE:ELECTION DAY'!N44) -> 0 | Q44: =SUM('ADVANCE:ELECTION DAY'!Q44) -> 0 | R44: =SUM('ADVANCE:ELECTION DAY'!R44) -> 0 | S44: =SUM('ADVANCE:ELECTION DAY'!S44) -> 0 | T44: =SUM('ADVANCE:ELECTION DAY'!T44) -> 0 | U44: =SUM('ADVANCE:ELECTION DAY'!U44) -> 0 | V44: =SUM('ADVANCE:ELECTION DAY'!V44) -> 0 | W44: =SUM('ADVANCE:ELECTION DAY'!W44) -> 0 | X44: =SUM('ADVANCE:ELECTION DAY'!X44) -> 0 | Y44: =E44+F44+G44+H44+I44+J44+K44+L44+M44+N44+Q44+R44+S44+T44+U44+V44+W44+X44 -> 0
B45: COUNTY REGISTER OF DEEDS | O45: COUNTY REGISTER OF DEEDS
C46: Dani Roeder | D46: Rep | E46: =SUM('ADVANCE:ELECTION DAY'!E46) -> 15 | F46: =SUM('ADVANCE:ELECTION DAY'!F46) -> 38 | G46: =SUM('ADVANCE:ELECTION DAY'!G46) -> 29 | H46: =SUM('ADVANCE:ELECTION DAY'!H46) -> 23 | I46: =SUM('ADVANCE:ELECTION DAY'!I46) -> 24 | J46: =SUM('ADVANCE:ELECTION DAY'!J46) -> 46 | K46: =SUM('ADVANCE:ELECTION DAY'!K46) -> 240 | L46: =SUM('ADVANCE:ELECTION DAY'!L46) -> 89 | ... N46: =SUM('ADVANCE:ELECTION DAY'!N46) -> 16 | O46: Dani Roeder | P46: Rep | Q46: =SUM('ADVANCE:ELECTION DAY'!Q46) -> 25 | R46: =SUM('ADVANCE:ELECTION DAY'!R46) -> 12 | S46: =SUM('ADVANCE:ELECTION DAY'!S46) -> 41 | T46: =SUM('ADVANCE:ELECTION DAY'!T46) -> 29 | U46: =SUM('ADVANCE:ELECTION DAY'!U46) -> 17 | V46: =SUM('ADVANCE:ELECTION DAY'!V46) -> 4 | W46: =SUM('ADVANCE:ELECTION DAY'!W46) -> 54 | X46: =SUM('ADVANCE:ELECTION DAY'!X46) -> 87 | Y46: =E46+F46+G46+H46+I46+J46+K46+L46+M46+N46+Q46+R46+S46+T46+U46+V46+W46+X46 -> 789
...

Sheet Abstract
B1: Abstract of Votes Cast at the Primary Election in | O1: Abstract of Votes Cast at the Primary Election in
B2: Graham County Kansas, on the 5th day of November, 2024 | O2: Graham County Kansas, on the 5th day of November, 2024
B3: Number of Voters Voting | C3: 1317
B4: Registered Voters | C4: 1808
B5: Turnout | C5: 0.73
B6: NAME OF OFFICE | C6: NAME OF PERSON VOTED FOR | D6: PARTY | E6: ALLODIUM | F6: BRYANT | G6: GETTYSBURG | H6: GRAHAM | I6: HAPPPY | J6: HILL CITY #1 | K6: HILL CITY #2 | L6: HILL CITY #3 | M6: HILL CITY TWP #71 | N6: HILL CITY TWP #72 | O6: NAME OF PERSON VOTED FOR | P6: PARTY | Q6: HILL CITY TWP #73 | R6: INDIANA | S6: MILLBROOK | T6: MORLAN | U6: NICODEMUS | V6: PIONEER | W6: SOLOMON | X6: WILDHORSE | Y6: TOTAL | Z6: PROVISIONAL | AA6: TOTAL
B7: PRESIDENT AND VICE PRESIDENT | O7: PRESIDENT AND VICE PRESIDENT
C8: Trump/Vance | D8: Rep. | E8: =SUM('ADVANCE & ELECTION DAY TOTAL'!E5) -> 20 | F8: =SUM('ADVANCE & ELECTION DAY TOTAL'!F5) -> 47 | G8: =SUM('ADVANCE & ELECTION DAY TOTAL'!G5) -> 37 | H8: =SUM('ADVANCE & ELECTION DAY TOTAL'!H5) -> 29 | I8: =SUM('ADVANCE & ELECTION DAY TOTAL'!I5) -> 22 | J8: =SUM('ADVANCE & ELECTION DAY TOTAL'!J5) -> 70 | K8: 318 | L8: 114 | M8: =SUM('ADVANCE & ELECTION DAY TOTAL'!M5) -> 6 | N8: =SUM('ADVANCE & ELECTION DAY TOTAL'!N5) -> 37 | O8: Trump/Vance | P8: Rep. | Q8: =SUM('ADVANCE & ELECTION DAY TOTAL'!Q5) -> 29 | R8: =SUM('ADVANCE & ELECTION DAY TOTAL'!R5) -> 15 | S8: =SUM('ADVANCE & ELECTION DAY TOTAL'!S5) -> 62 | T8: =SUM('ADVANCE & ELECTION DAY TOTAL'!T5) -> 30 | U8: =SUM('ADVANCE & ELECTION DAY TOTAL'!U5) -> 12 | V8: 17 | W8: =SUM('ADVANCE & ELECTION DAY TOTAL'!W5) -> 76 | X8: =SUM('ADVANCE & ELECTION DAY TOTAL'!X5) -> 92 | Y8: =SUM(E8:X8) -> 1033 | Z8: 22 | AA8: =SUM(Y8:Z8) -> 1055
C9: Harris/Walz | D9: Dem. | E9: =SUM('ADVANCE & ELECTION DAY TOTAL'!E6) -> 0 | F9: =SUM('ADVANCE & ELECTION DAY TOTAL'!F6) -> 5 | G9: =SUM('ADVANCE & ELECTION DAY TOTAL'!G6) -> 5 | H9: =SUM('ADVANCE & ELECTION DAY TOTAL'!H6) -> 7 | I9: =SUM('ADVANCE & ELECTION DAY TOTAL'!I6) -> 8 | J9: =SUM('ADVANCE & ELECTION DAY TOTAL'!J6) -> 15 | K9: 84 | L9: =SUM('ADVANCE & ELECTION DAY TOTAL'!L6) -> 28 | M9: =SUM('ADVANCE & ELECTION DAY TOTAL'!M6) -> 0 | N9: =SUM('ADVANCE & ELECTION DAY TOTAL'!N6) -> 7 | O9: Harris/Walz | P9: Dem. | Q9: =SUM('ADVANCE & ELECTION DAY TOTAL'!Q6) -> 3 | R9: =SUM('ADVANCE & ELECTION DAY TOTAL'!R6) -> 1 | S9: =SUM('ADVANCE & ELECTION DAY TOTAL'!S6) -> 8 | T9: =SUM('ADVANCE & ELECTION DAY TOTAL'!T6) -> 1 | U9: =SUM('ADVANCE & ELECTION DAY TOTAL'!U6) -> 9 | V9: =SUM('ADVANCE & ELECTION DAY TOTAL'!V6) -> 0 | W9: =SUM('ADVANCE & ELECTION DAY TOTAL'!W6) -> 9 | X9: =SUM('ADVANCE & ELECTION DAY TOTAL'!X6) -> 16 | Y9: =SUM(E9:X9) -> 206 | Z9: 4 | AA9: =SUM(Y9:Z9) -> 210
C10: Kennedy Jr./Shanahan | D10: Indep. | E10: =SUM('ADVANCE & ELECTION DAY TOTAL'!E7) -> 0 | F10: =SUM('ADVANCE & ELECTION DAY TOTAL'!F7) -> 0 | G10: =SUM('ADVANCE & ELECTION DAY TOTAL'!G7) -> 1 | H10: =SUM('ADVANCE & ELECTION DAY TOTAL'!H7) -> 0 | I10: =SUM('ADVANCE & ELECTION DAY TOTAL'!I7) -> 0 | J10: =SUM('ADVANCE & ELECTION DAY TOTAL'!J7) -> 3 | K10: 12 | L10: =SUM('ADVANCE & ELECTION DAY TOTAL'!L7) -> 1 | M10: =SUM('ADVANCE & ELECTION DAY TOTAL'!M7) -> 0 | N10: =SUM('ADVANCE & ELECTION DAY TOTAL'!N7) -> 0 | O10: Kennedy Jr./Shanahan | P10: Indep. | Q10: =SUM('ADVANCE & ELECTION DAY TOTAL'!Q7) -> 0 | R10: =SUM('ADVANCE & ELECTION DAY TOTAL'!R7) -> 1 | S10: =SUM('ADVANCE & ELECTION DAY TOTAL'!S7) -> 0 | T10: =SUM('ADVANCE & ELECTION DAY TOTAL'!T7) -> 0 | U10: =SUM('ADVANCE & ELECTION DAY TOTAL'!U7) -> 0 | V10: =SUM('ADVANCE & ELECTION DAY TOTAL'!V7) -> 0 | W10: =SUM('ADVANCE & ELECTION DAY TOTAL'!W7) -> 1 | X10: =SUM('ADVANCE & ELECTION DAY TOTAL'!X7) -> 0 | Y10: =SUM(E10:X10) -> 19 | Z10: 1 | AA10: =SUM(Y10:Z10) -> 20
C11: Oliver/ ter Maat | D11: Lib. | E11: =SUM('ADVANCE & ELECTION DAY TOTAL'!E8) -> 0 | F11: =SUM('ADVANCE & ELECTION DAY TOTAL'!F8) -> 0 | G11: =SUM('ADVANCE & ELECTION DAY TOTAL'!G8) -> 0 | H11: =SUM('ADVANCE & ELECTION DAY TOTAL'!H8) -> 0 | I11: =SUM('ADVANCE & ELECTION DAY TOTAL'!I8) -> 0 | J11: =SUM('ADVANCE & ELECTION DAY TOTAL'!J8) -> 0 | K11: =SUM('ADVANCE & ELECTION DAY TOTAL'!K8) -> 1 | L11: =SUM('ADVANCE & ELECTION DAY TOTAL'!L8) -> 0 | ... N11: =SUM('ADVANCE & ELECTION DAY TOTAL'!N8) -> 0 | O11: Oliver/ ter Maat | P11: Lib. | Q11: =SUM('ADVANCE & ELECTION DAY TOTAL'!Q8) -> 0 | R11: =SUM('ADVANCE & ELECTION DAY TOTAL'!R8) -> 0 | S11: =SUM('ADVANCE & ELECTION DAY TOTAL'!S8) -> 0 | T11: =SUM('ADVANCE & ELECTION DAY TOTAL'!T8) -> 0 | U11: =SUM('ADVANCE & ELECTION DAY TOTAL'!U8) -> 0 | V11: =SUM('ADVANCE & ELECTION DAY TOTAL'!V8) -> 0 | W11: =SUM('ADVANCE & ELECTION DAY TOTAL'!W8) -> 0 | X11: =SUM('ADVANCE & ELECTION DAY TOTAL'!X8) -> 0 | Y11: =SUM(E11:X11) -> 1 | Z11: 1 | AA11: =SUM(Y11:Z11) -> 2
B12: UNITED STATES REPRESENTATIVE 1ST DISTRICT | O12: UNITED STATES REPRESENTATIVE 1ST DISTRICT
C13: Paul Buskirk | D13: Dem. | E13: =SUM('ADVANCE & ELECTION DAY TOTAL'!E10) -> 0 | F13: =SUM('ADVANCE & ELECTION DAY TOTAL'!F10) -> 4 | G13: =SUM('ADVANCE & ELECTION DAY TOTAL'!G10) -> 4 | H13: =SUM('ADVANCE & ELECTION DAY TOTAL'!H10) -> 7 | I13: =SUM('ADVANCE & ELECTION DAY TOTAL'!I10) -> 6 | J13: =SUM('ADVANCE & ELECTION DAY TOTAL'!J10) -> 10 | K13: 71 | L13: =SUM('ADVANCE & ELECTION DAY TOTAL'!L10) -> 19 | M13: =SUM('ADVANCE & ELECTION DAY TOTAL'!M10) -> 0 | N13: =SUM('ADVANCE & ELECTION DAY TOTAL'!N10) -> 4 | O13: Paul Buskirk | P13: Dem. | Q13: =SUM('ADVANCE & ELECTION DAY TOTAL'!Q10) -> 0 | R13: =SUM('ADVANCE & ELECTION DAY TOTAL'!R10) -> 0 | S13: =SUM('ADVANCE & ELECTION DAY TOTAL'!S10) -> 6 | T13: =SUM('ADVANCE & ELECTION DAY TOTAL'!T10) -> 0 | U13: =SUM('ADVANCE & ELECTION DAY TOTAL'!U10) -> 8 | V13: =SUM('ADVANCE & ELECTION DAY TOTAL'!V10) -> 0 | W13: =SUM('ADVANCE & ELECTION DAY TOTAL'!W10) -> 6 | X13: 14 | Y13: =SUM(E13:X13) -> 159 | Z13: 1 | AA13: =SUM(Y13:Z13) -> 160
C14: Tracey Mann | D14: Rep. | E14: =SUM('ADVANCE & ELECTION DAY TOTAL'!E11) -> 20 | F14: =SUM('ADVANCE & ELECTION DAY TOTAL'!F11) -> 48 | G14: =SUM('ADVANCE & ELECTION DAY TOTAL'!G11) -> 39 | H14: =SUM('ADVANCE & ELECTION DAY TOTAL'!H11) -> 27 | I14: =SUM('ADVANCE & ELECTION DAY TOTAL'!I11) -> 24 | J14: =SUM('ADVANCE & ELECTION DAY TOTAL'!J11) -> 75 | K14: 330 | L14: 116 | M14: =SUM('ADVANCE & ELECTION DAY TOTAL'!M11) -> 6 | N14: =SUM('ADVANCE & ELECTION DAY TOTAL'!N11) -> 41 | O14: Tracey Mann | P14: Rep. | Q14: =SUM('ADVANCE & ELECTION DAY TOTAL'!Q11) -> 32 | R14: =SUM('ADVANCE & ELECTION DAY TOTAL'!R11) -> 17 | S14: =SUM('ADVANCE & ELECTION DAY TOTAL'!S11) -> 63 | T14: =SUM('ADVANCE & ELECTION DAY TOTAL'!T11) -> 30 | U14: =SUM('ADVANCE & ELECTION DAY TOTAL'!U11) -> 13 | V14: =SUM('ADVANCE & ELECTION DAY TOTAL'!V11) -> 14 | W14: =SUM('ADVANCE & ELECTION DAY TOTAL'!W11) -> 79 | X14: =SUM('ADVANCE & ELECTION DAY TOTAL'!X11) -> 94 | Y14: =SUM(E14:X14) -> 1068 | Z14: 27 | AA14: =SUM(Y14:Z14) -> 1095
E15: =SUM('ADVANCE & ELECTION DAY TOTAL'!E12) -> 0 | F15: =SUM('ADVANCE:ELECTION DAY'!F12) -> 0 | G15: =SUM('ADVANCE:ELECTION DAY'!G12) -> 0 | H15: =SUM('ADVANCE:ELECTION DAY'!H12) -> 0 | I15: =SUM('ADVANCE:ELECTION DAY'!I12) -> 0 | J15: =SUM('ADVANCE:ELECTION DAY'!J12) -> 0 | K15: =SUM('ADVANCE:ELECTION DAY'!K12) -> 0 | L15: =SUM('ADVANCE:ELECTION DAY'!L12) -> 0 | M15: =SUM('ADVANCE:ELECTION DAY'!M12) -> 0 | N15: =SUM('ADVANCE:ELECTION DAY'!N12) -> 0 | Q15: =SUM('ADVANCE & ELECTION DAY TOTAL'!Q12) -> 0 | R15: =SUM('ADVANCE & ELECTION DAY TOTAL'!R12) -> 0 | S15: =SUM('ADVANCE & ELECTION DAY TOTAL'!S12) -> 0 | T15: =SUM('ADVANCE & ELECTION DAY TOTAL'!T12) -> 0 | U15: =SUM('ADVANCE & ELECTION DAY TOTAL'!U12) -> 0 | V15: =SUM('ADVANCE & ELECTION DAY TOTAL'!V12) -> 0 | W15: =SUM('ADVANCE & ELECTION DAY TOTAL'!W12) -> 0 | X15: =SUM('ADVANCE & ELECTION DAY TOTAL'!X12) -> 0
B16: STATE SENATOR 40TH DISTRICT | O16: STATE SENATOR 40TH DISTRICT
C17: Richard (Rick) Billinger | D17: Rep. | E17: =SUM('ADVANCE & ELECTION DAY TOTAL'!E14) -> 20 | F17: =SUM('ADVANCE & ELECTION DAY TOTAL'!F14) -> 48 | G17: =SUM('ADVANCE & ELECTION DAY TOTAL'!G14) -> 41 | H17: =SUM('ADVANCE & ELECTION DAY TOTAL'!H14) -> 31 | I17: =SUM('ADVANCE & ELECTION DAY TOTAL'!I14) -> 28 | J17: =SUM('ADVANCE & ELECTION DAY TOTAL'!J14) -> 72 | K17: 351 | L17: 118 | M17: =SUM('ADVANCE & ELECTION DAY TOTAL'!M14) -> 5 | N17: =SUM('ADVANCE & ELECTION DAY TOTAL'!N14) -> 44 | O17: Richard (Rick) Billinger | Q17: =SUM('ADVANCE & ELECTION DAY TOTAL'!Q14) -> 32 | R17: =SUM('ADVANCE & ELECTION DAY TOTAL'!R14) -> 16 | S17: 67 | T17: =SUM('ADVANCE & ELECTION DAY TOTAL'!T14) -> 31 | U17: =SUM('ADVANCE & ELECTION DAY TOTAL'!U14) -> 18 | V17: =SUM('ADVANCE & ELECTION DAY TOTAL'!V14) -> 15 | W17: =SUM('ADVANCE & ELECTION DAY TOTAL'!W14) -> 76 | X17: 99 | Y17: =SUM(E17:X17) -> 1112 | Z17: 24 | AA17: =SUM(Y17:Z17) -> 1136
B18: STATE REPRESENTATIVE 110TH DISTRICT | O18: STATE REPRESENTATIVE 110TH DISTRICT
C19: ellace Henderson | D19: Dem. | E19: =SUM('ADVANCE & ELECTION DAY TOTAL'!E16) -> 0 | F19: =SUM('ADVANCE & ELECTION DAY TOTAL'!F16) -> 7 | G19: =SUM('ADVANCE & ELECTION DAY TOTAL'!G16) -> 5 | H19: =SUM('ADVANCE & ELECTION DAY TOTAL'!H16) -> 6 | I19: =SUM('ADVANCE & ELECTION DAY TOTAL'!I16) -> 7 | J19: =SUM('ADVANCE & ELECTION DAY TOTAL'!J16) -> 16 | K19: 72 | L19: =SUM('ADVANCE & ELECTION DAY TOTAL'!L16) -> 24 | M19: =SUM('ADVANCE & ELECTION DAY TOTAL'!M16) -> 0 | N19: =SUM('ADVANCE & ELECTION DAY TOTAL'!N16) -> 5 | O19: ellace Henderson | P19: Dem. | Q19: =SUM('ADVANCE & ELECTION DAY TOTAL'!Q16) -> 1 | R19: =SUM('ADVANCE & ELECTION DAY TOTAL'!R16) -> 2 | S19: =SUM('ADVANCE & ELECTION DAY TOTAL'!S16) -> 9 | T19: =SUM('ADVANCE & ELECTION DAY TOTAL'!T16) -> 0 | U19: =SUM('ADVANCE & ELECTION DAY TOTAL'!U16) -> 9 | V19: =SUM('ADVANCE & ELECTION DAY TOTAL'!V16) -> 1 | W19: =SUM('ADVANCE & ELECTION DAY TOTAL'!W16) -> 8 | X19: =SUM('ADVANCE & ELECTION DAY TOTAL'!X16) -> 13 | Y19: =SUM(E19:X19) -> 185 | Z19: 3 | AA19: =SUM(Y19:Z19) -> 188
C20: Ken Rahjes | D20: Rep. | E20: =SUM('ADVANCE & ELECTION DAY TOTAL'!E17) -> 20 | F20: =SUM('ADVANCE & ELECTION DAY TOTAL'!F17) -> 38 | G20: =SUM('ADVANCE & ELECTION DAY TOTAL'!G17) -> 39 | H20: =SUM('ADVANCE & ELECTION DAY TOTAL'!H17) -> 28 | I20: =SUM('ADVANCE & ELECTION DAY TOTAL'!I17) -> 23 | J20: =SUM('ADVANCE & ELECTION DAY TOTAL'!J17) -> 67 | K20: 310 | L20: 104 | M20: =SUM('ADVANCE & ELECTION DAY TOTAL'!M17) -> 5 | N20: =SUM('ADVANCE & ELECTION DAY TOTAL'!N17) -> 39 | O20: Ken Rahjes | P20: Rep. | Q20: =SUM('ADVANCE & ELECTION DAY TOTAL'!Q17) -> 30 | R20: =SUM('ADVANCE & ELECTION DAY TOTAL'!R17) -> 15 | S20: =SUM('ADVANCE & ELECTION DAY TOTAL'!S17) -> 58 | T20: =SUM('ADVANCE & ELECTION DAY TOTAL'!T17) -> 31 | U20: =SUM('ADVANCE & ELECTION DAY TOTAL'!U17) -> 12 | V20: =SUM('ADVANCE & ELECTION DAY TOTAL'!V17) -> 13 | W20: =SUM('ADVANCE & ELECTION DAY TOTAL'!W17) -> 76 | X20: =SUM('ADVANCE & ELECTION DAY TOTAL'!X17) -> 92 | Y20: =SUM(E20:X20) -> 1000 | Z20: 22 | AA20: =SUM(Y20:Z20) -> 1022
B21: DISTRICT COURT JUDGE 17TH DISTRICT 1ST DIVISION | O21: DISTRICT COURT JUDGE 17TH DISTRICT 1ST DIVISION
C22: Jesse A. Thompson | D22: Rep. | E22: 18 | F22: =SUM('ADVANCE & ELECTION DAY TOTAL'!F19) -> 43 | G22: =SUM('ADVANCE & ELECTION DAY TOTAL'!G19) -> 42 | H22: =SUM('ADVANCE & ELECTION DAY TOTAL'!H19) -> 31 | I22: =SUM('ADVANCE & ELECTION DAY TOTAL'!I19) -> 27 | J22: =SUM('ADVANCE & ELECTION DAY TOTAL'!J19) -> 72 | K22: 361 | L22: =SUM('ADVANCE & ELECTION DAY TOTAL'!L19) -> 127 | M22: =SUM('ADVANCE & ELECTION DAY TOTAL'!M19) -> 3 | N22: 41 | O22: Jesse A. Thompson | P22: Rep. | Q22: =SUM('ADVANCE & ELECTION DAY TOTAL'!Q19) -> 30 | R22: =SUM('ADVANCE & ELECTION DAY TOTAL'!R19) -> 16 | S22: 67 | T22: =SUM('ADVANCE & ELECTION DAY TOTAL'!T19) -> 26 | U22: =SUM('ADVANCE & ELECTION DAY TOTAL'!U19) -> 18 | V22: =SUM('ADVANCE & ELECTION DAY TOTAL'!V19) -> 15 | W22: =SUM('ADVANCE & ELECTION DAY TOTAL'!W19) -> 75 | X22: =SUM('ADVANCE & ELECTION DAY TOTAL'!X19) -> 99 | Y22: =SUM(E22:X22) -> 1111 | Z22: 26 | AA22: =SUM(Y22:Z22) -> 1137
E23: =SUM('ADVANCE & ELECTION DAY TOTAL'!E20) -> 0 | F23: =SUM('ADVANCE:ELECTION DAY'!F20) -> 0 | G23: =SUM('ADVANCE:ELECTION DAY'!G20) -> 0 | H23: =SUM('ADVANCE:ELECTION DAY'!H20) -> 0 | I23: =SUM('ADVANCE:ELECTION DAY'!I20) -> 0 | J23: =SUM('ADVANCE:ELECTION DAY'!J20) -> 0 | K23: =SUM('ADVANCE:ELECTION DAY'!K20) -> 0 | L23: =SUM('ADVANCE:ELECTION DAY'!L20) -> 0 | M23: =SUM('ADVANCE:ELECTION DAY'!M20) -> 0 | N23: =SUM('ADVANCE:ELECTION DAY'!N20) -> 0 | Q23: =SUM('ADVANCE & ELECTION DAY TOTAL'!Q20) -> 0 | R23: =SUM('ADVANCE & ELECTION DAY TOTAL'!R20) -> 0 | S23: =SUM('ADVANCE & ELECTION DAY TOTAL'!S20) -> 0 | T23: =SUM('ADVANCE & ELECTION DAY TOTAL'!T20) -> 0 | U23: =SUM('ADVANCE & ELECTION DAY TOTAL'!U20) -> 0 | V23: =SUM('ADVANCE & ELECTION DAY TOTAL'!V20) -> 0 | W23: =SUM('ADVANCE & ELECTION DAY TOTAL'!W20) -> 0 | X23: =SUM('ADVANCE & ELECTION DAY TOTAL'!X20) -> 0
B24: DISTRICT COURT JUDGE 17TH DISTRICT 2ND DIVISION | O24: DISTRICT COURT JUDGE 17TH DISTRICT 2ND DIVISION
C25: Paula D. Hofaker | D25: Rep. | E25: 19 | F25: =SUM('ADVANCE & ELECTION DAY TOTAL'!F22) -> 42 | G25: =SUM('ADVANCE & ELECTION DAY TOTAL'!G22) -> 40 | H25: =SUM('ADVANCE & ELECTION DAY TOTAL'!H22) -> 30 | I25: =SUM('ADVANCE & ELECTION DAY TOTAL'!I22) -> 25 | J25: =SUM('ADVANCE & ELECTION DAY TOTAL'!J22) -> 67 | K25: 342 | L25: 115 | M25: =SUM('ADVANCE & ELECTION DAY TOTAL'!M22) -> 4 | N25: =SUM('ADVANCE & ELECTION DAY TOTAL'!N22) -> 43 | O25: Paula D. Hofaker | P25: Rep. | Q25: =SUM('ADVANCE & ELECTION DAY TOTAL'!Q22) -> 29 | R25: =SUM('ADVANCE & ELECTION DAY TOTAL'!R22) -> 17 | S25: 64 | T25: =SUM('ADVANCE & ELECTION DAY TOTAL'!T22) -> 29 | U25: =SUM('ADVANCE & ELECTION DAY TOTAL'!U22) -> 17 | V25: 12 | W25: =SUM('ADVANCE & ELECTION DAY TOTAL'!W22) -> 74 | X25: =SUM('ADVANCE & ELECTION DAY TOTAL'!X22) -> 98 | Y25: =SUM(E25:X25) -> 1067 | Z25: 22 | AA25: =SUM(Y25:Z25) -> 1089
B26: DISTRICT MAGISTRATE JUDGE 17TH DISTRICT 1ST POSITION | O26: DISTRICT MAGISTRATE JUDGE 17TH DISTRICT 1ST POSITION
C27: Morgan Nutting | D27: Rep. | E27: =SUM('ADVANCE & ELECTION DAY TOTAL'!E24) -> 19 | F27: =SUM('ADVANCE & ELECTION DAY TOTAL'!F24) -> 41 | G27: =SUM('ADVANCE & ELECTION DAY TOTAL'!G24) -> 41 | H27: =SUM('ADVANCE & ELECTION DAY TOTAL'!H24) -> 31 | I27: =SUM('ADVANCE & ELECTION DAY TOTAL'!I24) -> 25 | J27: =SUM('ADVANCE & ELECTION DAY TOTAL'!J24) -> 74 | K27: 366 | L27: 129 | M27: =SUM('ADVANCE & ELECTION DAY TOTAL'!M24) -> 5 | N27: =SUM('ADVANCE & ELECTION DAY TOTAL'!N24) -> 38 | O27: Morgan Nutting | P27: Rep. | Q27: =SUM('ADVANCE & ELECTION DAY TOTAL'!Q24) -> 30 | R27: =SUM('ADVANCE & ELECTION DAY TOTAL'!R24) -> 16 | S27: =SUM('ADVANCE & ELECTION DAY TOTAL'!S24) -> 58 | T27: =SUM('ADVANCE & ELECTION DAY TOTAL'!T24) -> 26 | U27: =SUM('ADVANCE & ELECTION DAY TOTAL'!U24) -> 15 | V27: 17 | W27: =SUM('ADVANCE & ELECTION DAY TOTAL'!W24) -> 74 | X27: =SUM('ADVANCE & ELECTION DAY TOTAL'!X24) -> 99 | Y27: =SUM(E27:X27) -> 1104 | Z27: 26 | AA27: =SUM(Y27:Z27) -> 1130
O30: STATE OF KANSAS,
O31: Graham County, ss.
P32: We, the undersigned, members of the County Board of Canvassers for said County, do hereby
O33: certify that the foregoing abstract of votes cast at the General election held in Graham County on the 5th day of November A.D. 2024, is
O34: true and correct as shown by the returns of said election on file in the office of the County Election officer and canvassed by us
O35: this 15th day of November A.D. 2024.
O36: Witness our hands, this 15th day of November A.D. 2024.
O37: Attest: | S37: _____________________________
O38: _____________________________ | S38: _____________________________
O39: County Election Officer. | S39: _____________________________
T40: County Board of Canvassers.
B42: Abstract of Votes Cast at the Primary Election in | O42: Abstract of Votes Cast at the Primary Election in
B43: Graham County Kansas, on the 5th day of November, 2024 | O43: Graham County Kansas, on the 5th day of November, 2024
...
