Workbook

Sheet START

Sheet ADVANCE
B1: November 5th, 2024
B2: ADVANCE TOTALS
B3: NAME OF OFFICE | C3: NAME OF PERSON VOTED FOR | D3: PARTY | E3: ALLODIUM | F3: BRYANT | G3: GETTYSBURG | H3: GRAHAM | I3: HAPPPY | J3: HILL CITY #1 | K3: HILL CITY #2 | L3: HILL CITY #3 | M3: HILL CITY TWP #71 | N3: HILL CITY TWP #72 | O3: NAME OF PERSON VOTED FOR | P3: PARTY | Q3: HILL CITY TWP #73 | R3: INDIANA | S3: MILLBROOK | T3: MORLAN | U3: NICODEMUS | V3: PIONEER | W3: SOLOMON | X3: WILDHORSE | Y3: TOTAL
B4: HOSPITAL Board Pos. 4 | O4: HOSPITAL
C5: Michelle Smee | E5: 2 | G5: 2 | H5: 1 | I5: 2 | J5: 5 | K5: 31 | L5: 5 | N5: 2 | O5: Michelle Smee | Q5: 1 | S5: 3 | T5: 3 | V5: 4 | W5: 3 | X5: 6 | Y5: =SUM(D5:X5) -> 70
C6: Nikki Presley | E6: 1 | O6: Nikki Presley | Y6: =SUM(D6:X6) -> 1
C7: T. Treas | F7: 1 | O7: T. Treas | Y7: =SUM(D7:X7) -> 1
C8: Mark Fergeson | F8: 2 | O8: Mark Fergeson | Y8: =SUM(D8:X8) -> 2
C9: Cody Keiswetter | H9: 1 | O9: Cody Keiswetter | Y9: =SUM(D9:X9) -> 1
C10: Connie Gish | I10: 1 | O10: Connie Gish | S10: 1 | Y10: =SUM(D10:X10) -> 2
C11: Michelle Billips | J11: 1 | L11: 1 | O11: Michelle Billips | Y11: =SUM(D11:X11) -> 2
C12: Rhonda Goddard | J12: 1 | O12: Rhonda Goddard | Y12: =SUM(D12:X12) -> 1
C13: Chris Smee | J13: 1 | L13: 1 | O13: Chris Smee | Y13: =SUM(D13:X13) -> 2
C14: Dan Irby | K14: 2 | N14: 1 | O14: Dan Irby | S14: 1 | W14: 1 | Y14: =SUM(D14:X14) -> 5
C15: Dan Worcester | K15: 1 | O15: Dan Worcester | Y15: =SUM(D15:X15) -> 1
C16: David Atkins | K16: 1 | O16: David Atkins | Y16: =SUM(D16:X16) -> 1
C17: Marcy Gansel | K17: 1 | O17: Marcy Gansel | Y17: =SUM(D17:X17) -> 1
C18: Cindy Underhill | K18: 1 | L18: 1 | M18: 1 | N18: 1 | O18: Cindy Underhill | Y18: =SUM(D18:X18) -> 4
C19: Kay Money | K19: 1 | O19: Kay Money | X19: 1 | Y19: =SUM(D19:X19) -> 2
C20: Kimberly Kinderknecht | K20: 1 | O20: Kimberly Kinderknecht | Y20: =SUM(D20:X20) -> 1
C21: Ethan Edwards | K21: 1 | O21: Ethan Edwards | Y21: =SUM(D21:X21) -> 1
C22: Ron Radcliffe | K22: 1 | O22: Ron Radcliffe | Y22: =SUM(D22:X22) -> 1
C23: Joyce Reese | K23: 1 | O23: Joyce Reese | Y23: =SUM(D23:X23) -> 1
C24: Lance Post | K24: 1 | L24: 2 | N24: 1 | O24: Lance Post | Y24: =SUM(D24:X24) -> 4
C25: Saundra Nickelson | K25: 1 | O25: Saundra Nickelson | Y25: =SUM(D25:X25) -> 1
C26: Reggie Jordan | K26: 1 | O26: Reggie Jordan | Y26: =SUM(D26:X26) -> 1
C27: Cole Keiswetter | K27: 1 | O27: Cole Keiswetter | Y27: =SUM(D27:X27) -> 1
C28: Joy Robison | K28: 1 | O28: Joy Robison | Y28: =SUM(D28:X28) -> 1
C29: Dannis Robison | K29: 1 | O29: Dannis Robison | Y29: =SUM(D29:X29) -> 1
C30: Bruce VanLoenen | K30: 1 | O30: Bruce VanLoenen | Y30: =SUM(D30:X30) -> 1
C31: Missy Atkins | L31: 1 | O31: Missy Atkins | Y31: =SUM(L31:X31) -> 1
C32: Mike Parks | L32: 1 | O32: Mike Parks | Y32: =SUM(L32:X32) -> 1
C33: Curt Hamel | L33: 1 | O33: Curt Hamel | Y33: =SUM(D33:X33) -> 1
C34: Dr. Handy | L34: 1 | O34: Dr. Handy | Y34: =SUM(D34:X34) -> 1
C35: Dennis Mersch | L35: 1 | N35: 1 | O35: Dennis Mersch | Y35: =SUM(D35:X35) -> 2
C36: Debra Tremblay | L36: 1 | O36: Debra Tremblay | Y36: =SUM(D36:X36) -> 1
C37: Teri Cooper | M37: 1 | O37: Teri Cooper | Y37: =SUM(D37:X37) -> 1
C38: Brandy Born | N38: 2 | O38: Brandy Born | Y38: =SUM(D38:X38) -> 2
C39: Jessica Smith | O39: Jessica Smith | Q39: 1 | Y39: =SUM(D39:X39) -> 1
C40: Shawn Brown | O40: Shawn Brown | Q40: 1 | Y40: =SUM(D40:X40) -> 1
...

Sheet ELECTION DAY
B1: November 5th, 2024
B2: ELECTION DAY TOTALS
B3: NAME OF OFFICE | C3: NAME OF PERSON VOTED FOR | D3: PARTY | E3: ALLODIUM | F3: BRYANT | G3: GETTYSBURG | H3: GRAHAM | I3: HAPPPY | J3: HILL CITY #1 | K3: HILL CITY #2 | L3: HILL CITY #3 | M3: HILL CITY TWP #71 | N3: HILL CITY TWP #72 | O3: NAME OF PERSON VOTED FOR | P3: PARTY | Q3: HILL CITY TWP #73 | R3: INDIANA | S3: MILLBROOK | T3: MORLAN | U3: NICODEMUS | V3: PIONEER | W3: SOLOMON | X3: WILDHORSE | Y3: TOTAL
B4: HOSPITAL Board Pos. 4 | O4: HOSPITAL
C5: Michelle Smee | G5: 3 | H5: 3 | J5: 4 | K5: 27 | L5: 2 | N5: 5 | O5: Michelle Smee | Q5: 3 | R5: 1 | S5: 2 | U5: 1 | V5: 3 | X5: 4 | Y5: =SUM(D5:X5) -> 58
C6: Nikki Presley | O6: Nikki Presley | Y6: =SUM(D6:X6) -> 0
C7: T. Treas | O7: T. Treas | Y7: =SUM(D7:X7) -> 0
C8: Mark Fergeson | O8: Mark Fergeson | Y8: =SUM(D8:X8) -> 0
C9: Cody Keiswetter | O9: Cody Keiswetter | Y9: =SUM(D9:X9) -> 0
C10: Connie Gish | L10: 1 | O10: Connie Gish | Y10: =SUM(D10:X10) -> 1
C11: Michelle Billips | O11: Michelle Billips | Y11: =SUM(D11:X11) -> 0
C12: Rhonda Goddard | O12: Rhonda Goddard | Y12: =SUM(D12:X12) -> 0
C13: Chris Smee | O13: Chris Smee | Y13: =SUM(D13:X13) -> 0
C14: Dan Irby | E14: 2 | J14: 1 | K14: 1 | O14: Dan Irby | Y14: =SUM(D14:X14) -> 4
C15: Dan Worcester | O15: Dan Worcester | Y15: =SUM(D15:X15) -> 0
C16: David Atkins | O16: David Atkins | W16: 1 | Y16: =SUM(D16:X16) -> 1
C17: Marcy Gansel | O17: Marcy Gansel | Y17: =SUM(D17:X17) -> 0
C18: Cindy Underhill | O18: Cindy Underhill | Y18: =SUM(D18:X18) -> 0
C19: Kay Money | O19: Kay Money | Y19: =SUM(D19:X19) -> 0
C20: Kimberly Kinderknecht | O20: Kimberly Kinderknecht | Y20: =SUM(D20:X20) -> 0
C21: Ethan Edwards | O21: Ethan Edwards | Y21: =SUM(D21:X21) -> 0
C22: Ron Radcliffe | O22: Ron Radcliffe | Y22: =SUM(D22:X22) -> 0
C23: Joyce Reese | O23: Joyce Reese | Y23: =SUM(D23:X23) -> 0
C24: Lance Post | L24: 1 | O24: Lance Post | Y24: =SUM(D24:X24) -> 1
C25: Saundra Nickelson | O25: Saundra Nickelson | Y25: =SUM(D25:X25) -> 0
C26: Reggie Jordan | O26: Reggie Jordan | Y26: =SUM(D26:X26) -> 0
C27: Cole Keiswetter | O27: Cole Keiswetter | Y27: =SUM(D27:X27) -> 0
C28: Joy Robison | O28: Joy Robison | Y28: =SUM(D28:X28) -> 0
C29: Dannis Robison | O29: Dannis Robison | Y29: =SUM(D29:X29) -> 0
C30: Bruce VanLoenen | K30: 1 | L30: 1 | O30: Bruce VanLoenen | Y30: =SUM(D30:X30) -> 2
C31: Missy Atkins | O31: Missy Atkins | Y31: =SUM(L31:X31) -> 0
C32: Mike Parks | O32: Mike Parks | Y32: =SUM(L32:X32) -> 0
C33: Curt Hamel | O33: Curt Hamel | Y33: =SUM(D33:X33) -> 0
C34: Dr. Handy | O34: Dr. Handy | Y34: =SUM(D34:X34) -> 0
C35: Dennis Mersch | O35: Dennis Mersch | Y35: =SUM(D35:X35) -> 0
C36: Debra Tremblay | O36: Debra Tremblay | Y36: =SUM(D36:X36) -> 0
C37: Teri Cooper | O37: Teri Cooper | Y37: =SUM(D37:X37) -> 0
C38: Brandy Born | J38: 1 | O38: Brandy Born | Y38: =SUM(D38:X38) -> 1
C39: Jessica Smith | O39: Jessica Smith | Y39: =SUM(D39:X39) -> 0
C40: Shawn Brown | O40: Shawn Brown | Y40: =SUM(D40:X40) -> 0
...

Sheet END

Sheet ADVANCE & ELECTION DAY TOTAL
B1: November 5th, 2024
B2: TOTALS
B3: NAME OF OFFICE | C3: NAME OF PERSON VOTED FOR | D3: PARTY | E3: ALLODIUM | F3: BRYANT | G3: GETTYSBURG | H3: GRAHAM | I3: HAPPPY | J3: HILL CITY #1 | K3: HILL CITY #2 | L3: HILL CITY #3 | M3: HILL CITY TWP #71 | N3: HILL CITY TWP #72 | O3: NAME OF PERSON VOTED FOR | P3: PARTY | Q3: HILL CITY TWP #73 | R3: INDIANA | S3: MILLBROOK | T3: MORLAN | U3: NICODEMUS | V3: PIONEER | W3: SOLOMON | X3: WILDHORSE | Y3: TOTAL
B4: HOSPITAL Board Pos. 4 | O4: HOSPITAL
C5: Michelle Smee | E5: =SUM(START:END!E5) -> 2 | F5: =SUM(START:END!F5) -> 0 | G5: =SUM(START:END!G5) -> 5 | H5: =SUM(START:END!H5) -> 4 | I5: =SUM(START:END!I5) -> 2 | J5: =SUM(START:END!J5) -> 9 | K5: =SUM(START:END!K5) -> 58 | L5: =SUM(START:END!L5) -> 7 | ... N5: =SUM(START:END!N5) -> 7 | O5: Michelle Smee | Q5: =SUM(START:END!Q5) -> 4 | R5: =SUM(START:END!R5) -> 1 | S5: =SUM(START:END!S5) -> 5 | T5: =SUM(START:END!T5) -> 3 | U5: =SUM(START:END!U5) -> 1 | V5: =SUM(START:END!V5) -> 7 | W5: =SUM(START:END!W5) -> 3 | X5: =SUM(START:END!X5) -> 10 | Y5: =SUM(D5:X5) -> 128
C6: Nikki Presley | E6: =SUM(START:END!E6) -> 1 | F6: =SUM(START:END!F6) -> 0 | G6: =SUM(START:END!G6) -> 0 | H6: =SUM(START:END!H6) -> 0 | I6: =SUM(START:END!I6) -> 0 | J6: =SUM(START:END!J6) -> 0 | K6: =SUM(START:END!K6) -> 0 | L6: =SUM(START:END!L6) -> 0 | ... N6: =SUM(START:END!N6) -> 0 | O6: Nikki Presley | Q6: =SUM(START:END!Q6) -> 0 | R6: =SUM(START:END!R6) -> 0 | S6: =SUM(START:END!S6) -> 0 | T6: =SUM(START:END!T6) -> 0 | U6: =SUM(START:END!U6) -> 0 | V6: =SUM(START:END!V6) -> 0 | W6: =SUM(START:END!W6) -> 0 | X6: =SUM(START:END!X6) -> 0 | Y6: =SUM(D6:X6) -> 1
C7: T. Treas | E7: =SUM(START:END!E7) -> 0 | F7: =SUM(START:END!F7) -> 1 | G7: =SUM(START:END!G7) -> 0 | H7: =SUM(START:END!H7) -> 0 | I7: =SUM(START:END!I7) -> 0 | J7: =SUM(START:END!J7) -> 0 | K7: =SUM(START:END!K7) -> 0 | L7: =SUM(START:END!L7) -> 0 | ... N7: =SUM(START:END!N7) -> 0 | O7: T. Treas | Q7: =SUM(START:END!Q7) -> 0 | R7: =SUM(START:END!R7) -> 0 | S7: =SUM(START:END!S7) -> 0 | T7: =SUM(START:END!T7) -> 0 | U7: =SUM(START:END!U7) -> 0 | V7: =SUM(START:END!V7) -> 0 | W7: =SUM(START:END!W7) -> 0 | X7: =SUM(START:END!X7) -> 0 | Y7: =SUM(D7:X7) -> 1
C8: Mark Fergeson | E8: =SUM(START:END!E8) -> 0 | F8: =SUM(START:END!F8) -> 2 | G8: =SUM(START:END!G8) -> 0 | H8: =SUM(START:END!H8) -> 0 | I8: =SUM(START:END!I8) -> 0 | J8: =SUM(START:END!J8) -> 0 | K8: =SUM(START:END!K8) -> 0 | L8: =SUM(START:END!L8) -> 0 | ... N8: =SUM(START:END!N8) -> 0 | O8: Mark Fergeson | Q8: =SUM(START:END!Q8) -> 0 | R8: =SUM(START:END!R8) -> 0 | S8: =SUM(START:END!S8) -> 0 | T8: =SUM(START:END!T8) -> 0 | U8: =SUM(START:END!U8) -> 0 | V8: =SUM(START:END!V8) -> 0 | W8: =SUM(START:END!W8) -> 0 | X8: =SUM(START:END!X8) -> 0 | Y8: =SUM(D8:X8) -> 2
C9: Cody Keiswetter | E9: =SUM(START:END!E9) -> 0 | F9: =SUM(START:END!F9) -> 0 | G9: =SUM(START:END!G9) -> 0 | H9: =SUM(START:END!H9) -> 1 | I9: =SUM(START:END!I9) -> 0 | J9: =SUM(START:END!J9) -> 0 | K9: =SUM(START:END!K9) -> 0 | L9: =SUM(START:END!L9) -> 0 | ... N9: =SUM(START:END!N9) -> 0 | O9: Cody Keiswetter | Q9: =SUM(START:END!Q9) -> 0 | R9: =SUM(START:END!R9) -> 0 | S9: =SUM(START:END!S9) -> 0 | T9: =SUM(START:END!T9) -> 0 | U9: =SUM(START:END!U9) -> 0 | V9: =SUM(START:END!V9) -> 0 | W9: =SUM(START:END!W9) -> 0 | X9: =SUM(START:END!X9) -> 0 | Y9: =SUM(D9:X9) -> 1
C10: Connie Gish | E10: =SUM(START:END!E10) -> 0 | F10: =SUM(START:END!F10) -> 0 | G10: =SUM(START:END!G10) -> 0 | H10: =SUM(START:END!H10) -> 0 | I10: =SUM(START:END!I10) -> 1 | J10: =SUM(START:END!J10) -> 0 | K10: =SUM(START:END!K10) -> 0 | L10: =SUM(START:END!L10) -> 1 | ... N10: =SUM(START:END!N10) -> 0 | O10: Connie Gish | Q10: =SUM(START:END!Q10) -> 0 | R10: =SUM(START:END!R10) -> 0 | S10: =SUM(START:END!S10) -> 1 | T10: =SUM(START:END!T10) -> 0 | U10: =SUM(START:END!U10) -> 0 | V10: =SUM(START:END!V10) -> 0 | W10: =SUM(START:END!W10) -> 0 | X10: =SUM(START:END!X10) -> 0 | Y10: =SUM(D10:X10) -> 3
C11: Michelle Billips | E11: =SUM(START:END!E11) -> 0 | F11: =SUM(START:END!F11) -> 0 | G11: =SUM(START:END!G11) -> 0 | H11: =SUM(START:END!H11) -> 0 | I11: =SUM(START:END!I11) -> 0 | J11: =SUM(START:END!J11) -> 1 | K11: =SUM(START:END!K11) -> 0 | L11: =SUM(START:END!L11) -> 1 | ... N11: =SUM(START:END!N11) -> 0 | O11: Michelle Billips | Q11: =SUM(START:END!Q11) -> 0 | R11: =SUM(START:END!R11) -> 0 | S11: =SUM(START:END!S11) -> 0 | T11: =SUM(START:END!T11) -> 0 | U11: =SUM(START:END!U11) -> 0 | V11: =SUM(START:END!V11) -> 0 | W11: =SUM(START:END!W11) -> 0 | X11: =SUM(START:END!X11) -> 0 | Y11: =SUM(D11:X11) -> 2
C12: Rhonda Goddard | E12: =SUM(START:END!E12) -> 0 | F12: =SUM(START:END!F12) -> 0 | G12: =SUM(START:END!G12) -> 0 | H12: =SUM(START:END!H12) -> 0 | I12: =SUM(START:END!I12) -> 0 | J12: =SUM(START:END!J12) -> 1 | K12: =SUM(START:END!K12) -> 0 | L12: =SUM(START:END!L12) -> 0 | ... N12: =SUM(START:END!N12) -> 0 | O12: Rhonda Goddard | Q12: =SUM(START:END!Q12) -> 0 | R12: =SUM(START:END!R12) -> 0 | S12: =SUM(START:END!S12) -> 0 | T12: =SUM(START:END!T12) -> 0 | U12: =SUM(START:END!U12) -> 0 | V12: =SUM(START:END!V12) -> 0 | W12: =SUM(START:END!W12) -> 0 | X12: =SUM(START:END!X12) -> 0 | Y12: =SUM(D12:X12) -> 1
C13: Chris Smee | E13: =SUM(START:END!E13) -> 0 | F13: =SUM(START:END!F13) -> 0 | G13: =SUM(START:END!G13) -> 0 | H13: =SUM(START:END!H13) -> 0 | I13: =SUM(START:END!I13) -> 0 | J13: =SUM(START:END!J13) -> 1 | K13: =SUM(START:END!K13) -> 0 | L13: =SUM(START:END!L13) -> 1 | ... N13: =SUM(START:END!N13) -> 0 | O13: Chris Smee | Q13: =SUM(START:END!Q13) -> 0 | R13: =SUM(START:END!R13) -> 0 | S13: =SUM(START:END!S13) -> 0 | T13: =SUM(START:END!T13) -> 0 | U13: =SUM(START:END!U13) -> 0 | V13: =SUM(START:END!V13) -> 0 | W13: =SUM(START:END!W13) -> 0 | X13: =SUM(START:END!X13) -> 0 | Y13: =SUM(D13:X13) -> 2
C14: Dan Irby | E14: =SUM(START:END!E14) -> 2 | F14: =SUM(START:END!F14) -> 0 | G14: =SUM(START:END!G14) -> 0 | H14: =SUM(START:END!H14) -> 0 | I14: =SUM(START:END!I14) -> 0 | J14: =SUM(START:END!J14) -> 1 | K14: =SUM(START:END!K14) -> 3 | L14: =SUM(START:END!L14) -> 0 | ... N14: =SUM(START:END!N14) -> 1 | O14: Dan Irby | Q14: =SUM(START:END!Q14) -> 0 | R14: =SUM(START:END!R14) -> 0 | S14: =SUM(START:END!S14) -> 1 | T14: =SUM(START:END!T14) -> 0 | U14: =SUM(START:END!U14) -> 0 | V14: =SUM(START:END!V14) -> 0 | W14: =SUM(START:END!W14) -> 1 | X14: =SUM(START:END!X14) -> 0 | Y14: =SUM(D14:X14) -> 9
C15: Dan Worcester | E15: =SUM(START:END!E15) -> 0 | F15: =SUM(START:END!F15) -> 0 | G15: =SUM(START:END!G15) -> 0 | H15: =SUM(START:END!H15) -> 0 | I15: =SUM(START:END!I15) -> 0 | J15: =SUM(START:END!J15) -> 0 | K15: =SUM(START:END!K15) -> 1 | L15: =SUM(START:END!L15) -> 0 | ... N15: =SUM(START:END!N15) -> 0 | O15: Dan Worcester | Q15: =SUM(START:END!Q15) -> 0 | R15: =SUM(START:END!R15) -> 0 | S15: =SUM(START:END!S15) -> 0 | T15: =SUM(START:END!T15) -> 0 | U15: =SUM(START:END!U15) -> 0 | V15: =SUM(START:END!V15) -> 0 | W15: =SUM(START:END!W15) -> 0 | X15: =SUM(START:END!X15) -> 0 | Y15: =SUM(D15:X15) -> 1
C16: David Atkins | E16: =SUM(START:END!E16) -> 0 | F16: =SUM(START:END!F16) -> 0 | G16: =SUM(START:END!G16) -> 0 | H16: =SUM(START:END!H16) -> 0 | I16: =SUM(START:END!I16) -> 0 | J16: =SUM(START:END!J16) -> 0 | K16: =SUM(START:END!K16) -> 1 | L16: =SUM(START:END!L16) -> 0 | ... N16: =SUM(START:END!N16) -> 0 | O16: David Atkins | Q16: =SUM(START:END!Q16) -> 0 | R16: =SUM(START:END!R16) -> 0 | S16: =SUM(START:END!S16) -> 0 | T16: =SUM(START:END!T16) -> 0 | U16: =SUM(START:END!U16) -> 0 | V16: =SUM(START:END!V16) -> 0 | W16: =SUM(START:END!W16) -> 1 | X16: =SUM(START:END!X16) -> 0 | Y16: =SUM(D16:X16) -> 2
... C30: Bruce VanLoenen | E30: =SUM(START:END!E30) -> 0 | F30: =SUM(START:END!F30) -> 0 | G30: =SUM(START:END!G30) -> 0 | H30: =SUM(START:END!H30) -> 0 | I30: =SUM(START:END!I30) -> 0 | J30: =SUM(START:END!J30) -> 0 | K30: =SUM(START:END!K30) -> 2 | L30: =SUM(START:END!L30) -> 1 | ... N30: =SUM(START:END!N30) -> 0 | O30: Bruce VanLoenen | Q30: =SUM(START:END!Q30) -> 0 | R30: =SUM(START:END!R30) -> 0 | S30: =SUM(START:END!S30) -> 0 | T30: =SUM(START:END!T30) -> 0 | U30: =SUM(START:END!U30) -> 0 | V30: =SUM(START:END!V30) -> 0 | W30: =SUM(START:END!W30) -> 0 | X30: =SUM(START:END!X30) -> 0 | Y30: =SUM(D30:X30) -> 3
C31: Missy Atkins | E31: =SUM(START:END!E31) -> 0 | F31: =SUM(START:END!F31) -> 0 | G31: =SUM(START:END!G31) -> 0 | H31: =SUM(START:END!H31) -> 0 | I31: =SUM(START:END!I31) -> 0 | J31: =SUM(START:END!J31) -> 0 | K31: =SUM(START:END!K31) -> 0 | L31: =SUM(START:END!L31) -> 1 | ... N31: =SUM(START:END!N31) -> 0 | O31: Missy Atkins | Q31: =SUM(START:END!Q31) -> 0 | R31: =SUM(START:END!R31) -> 0 | S31: =SUM(START:END!S31) -> 0 | T31: =SUM(START:END!T31) -> 0 | U31: =SUM(START:END!U31) -> 0 | V31: =SUM(START:END!V31) -> 0 | W31: =SUM(START:END!W31) -> 0 | X31: =SUM(START:END!X31) -> 0 | Y31: =SUM(L31:X31) -> 1
C32: Mike Parks | E32: =SUM(START:END!E32) -> 0 | F32: =SUM(START:END!F32) -> 0 | G32: =SUM(START:END!G32) -> 0 | H32: =SUM(START:END!H32) -> 0 | I32: =SUM(START:END!I32) -> 0 | J32: =SUM(START:END!J32) -> 0 | K32: =SUM(START:END!K32) -> 0 | L32: =SUM(START:END!L32) -> 1 | ... N32: =SUM(START:END!N32) -> 0 | O32: Mike Parks | Q32: =SUM(START:END!Q32) -> 0 | R32: =SUM(START:END!R32) -> 0 | S32: =SUM(START:END!S32) -> 0 | T32: =SUM(START:END!T32) -> 0 | U32: =SUM(START:END!U32) -> 0 | V32: =SUM(START:END!V32) -> 0 | W32: =SUM(START:END!W32) -> 0 | X32: =SUM(START:END!X32) -> 0 | Y32: =SUM(L32:X32) -> 1
C33: Curt Hamel | E33: =SUM(START:END!E33) -> 0 | F33: =SUM(START:END!F33) -> 0 | G33: =SUM(START:END!G33) -> 0 | H33: =SUM(START:END!H33) -> 0 | I33: =SUM(START:END!I33) -> 0 | J33: =SUM(START:END!J33) -> 0 | K33: =SUM(START:END!K33) -> 0 | L33: =SUM(START:END!L33) -> 1 | ... N33: =SUM(START:END!N33) -> 0 | O33: Curt Hamel | Q33: =SUM(START:END!Q33) -> 0 | R33: =SUM(START:END!R33) -> 0 | S33: =SUM(START:END!S33) -> 0 | T33: =SUM(START:END!T33) -> 0 | U33: =SUM(START:END!U33) -> 0 | V33: =SUM(START:END!V33) -> 0 | W33: =SUM(START:END!W33) -> 0 | X33: =SUM(START:END!X33) -> 0 | Y33: =SUM(D33:X33) -> 1
C34: Dr. Handy | E34: =SUM(START:END!E34) -> 0 | F34: =SUM(START:END!F34) -> 0 | G34: =SUM(START:END!G34) -> 0 | H34: =SUM(START:END!H34) -> 0 | I34: =SUM(START:END!I34) -> 0 | J34: =SUM(START:END!J34) -> 0 | K34: =SUM(START:END!K34) -> 0 | L34: =SUM(START:END!L34) -> 1 | ... N34: =SUM(START:END!N34) -> 0 | O34: Dr. Handy | Q34: =SUM(START:END!Q34) -> 0 | R34: =SUM(START:END!R34) -> 0 | S34: =SUM(START:END!S34) -> 0 | T34: =SUM(START:END!T34) -> 0 | U34: =SUM(START:END!U34) -> 0 | V34: =SUM(START:END!V34) -> 0 | W34: =SUM(START:END!W34) -> 0 | X34: =SUM(START:END!X34) -> 0 | Y34: =SUM(D34:X34) -> 1
C35: Dennis Mersch | E35: =SUM(START:END!E35) -> 0 | F35: =SUM(START:END!F35) -> 0 | G35: =SUM(START:END!G35) -> 0 | H35: =SUM(START:END!H35) -> 0 | I35: =SUM(START:END!I35) -> 0 | J35: =SUM(START:END!J35) -> 0 | K35: =SUM(START:END!K35) -> 0 | L35: =SUM(START:END!L35) -> 1 | ... N35: =SUM(START:END!N35) -> 1 | O35: Dennis Mersch | Q35: =SUM(START:END!Q35) -> 0 | R35: =SUM(START:END!R35) -> 0 | S35: =SUM(START:END!S35) -> 0 | T35: =SUM(START:END!T35) -> 0 | U35: =SUM(START:END!U35) -> 0 | V35: =SUM(START:END!V35) -> 0 | W35: =SUM(START:END!W35) -> 0 | X35: =SUM(START:END!X35) -> 0 | Y35: =SUM(D35:X35) -> 2
C36: Debra Tremblay | E36: =SUM(START:END!E36) -> 0 | F36: =SUM(START:END!F36) -> 0 | G36: =SUM(START:END!G36) -> 0 | H36: =SUM(START:END!H36) -> 0 | I36: =SUM(START:END!I36) -> 0 | J36: =SUM(START:END!J36) -> 0 | K36: =SUM(START:END!K36) -> 0 | L36: =SUM(START:END!L36) -> 1 | ... N36: =SUM(START:END!N36) -> 0 | O36: Debra Tremblay | Q36: =SUM(START:END!Q36) -> 0 | R36: =SUM(START:END!R36) -> 0 | S36: =SUM(START:END!S36) -> 0 | T36: =SUM(START:END!T36) -> 0 | U36: =SUM(START:END!U36) -> 0 | V36: =SUM(START:END!V36) -> 0 | W36: =SUM(START:END!W36) -> 0 | X36: =SUM(START:END!X36) -> 0 | Y36: =SUM(D36:X36) -> 1
C37: Teri Cooper | E37: =SUM(START:END!E37) -> 0 | F37: =SUM(START:END!F37) -> 0 | G37: =SUM(START:END!G37) -> 0 | H37: =SUM(START:END!H37) -> 0 | I37: =SUM(START:END!I37) -> 0 | J37: =SUM(START:END!J37) -> 0 | K37: =SUM(START:END!K37) -> 0 | L37: =SUM(START:END!L37) -> 0 | ... N37: =SUM(START:END!N37) -> 0 | O37: Teri Cooper | Q37: =SUM(START:END!Q37) -> 0 | R37: =SUM(START:END!R37) -> 0 | S37: =SUM(START:END!S37) -> 0 | T37: =SUM(START:END!T37) -> 0 | U37: =SUM(START:END!U37) -> 0 | V37: =SUM(START:END!V37) -> 0 | W37: =SUM(START:END!W37) -> 0 | X37: =SUM(START:END!X37) -> 0 | Y37: =SUM(D37:X37) -> 1
C38: Brandy Born | E38: =SUM(START:END!E38) -> 0 | F38: =SUM(START:END!F38) -> 0 | G38: =SUM(START:END!G38) -> 0 | H38: =SUM(START:END!H38) -> 0 | I38: =SUM(START:END!I38) -> 0 | J38: =SUM(START:END!J38) -> 1 | K38: =SUM(START:END!K38) -> 0 | L38: =SUM(START:END!L38) -> 0 | ... N38: =SUM(START:END!N38) -> 2 | O38: Brandy Born | Q38: =SUM(START:END!Q38) -> 0 | R38: =SUM(START:END!R38) -> 0 | S38: =SUM(START:END!S38) -> 0 | T38: =SUM(START:END!T38) -> 0 | U38: =SUM(START:END!U38) -> 0 | V38: =SUM(START:END!V38) -> 0 | W38: =SUM(START:END!W38) -> 0 | X38: =SUM(START:END!X38) -> 0 | Y38: =SUM(D38:X38) -> 3
C39: Jessica Smith | E39: =SUM(START:END!E39) -> 0 | F39: =SUM(START:END!F39) -> 0 | G39: =SUM(START:END!G39) -> 0 | H39: =SUM(START:END!H39) -> 0 | I39: =SUM(START:END!I39) -> 0 | J39: =SUM(START:END!J39) -> 0 | K39: =SUM(START:END!K39) -> 0 | L39: =SUM(START:END!L39) -> 0 | ... N39: =SUM(START:END!N39) -> 0 | O39: Jessica Smith | Q39: =SUM(START:END!Q39) -> 1 | R39: =SUM(START:END!R39) -> 0 | S39: =SUM(START:END!S39) -> 0 | T39: =SUM(START:END!T39) -> 0 | U39: =SUM(START:END!U39) -> 0 | V39: =SUM(START:END!V39) -> 0 | W39: =SUM(START:END!W39) -> 0 | X39: =SUM(START:END!X39) -> 0 | Y39: =SUM(D39:X39) -> 1
C40: Shawn Brown | E40: =SUM(START:END!E40) -> 0 | F40: =SUM(START:END!F40) -> 0 | G40: =SUM(START:END!G40) -> 0 | H40: =SUM(START:END!H40) -> 0 | I40: =SUM(START:END!I40) -> 0 | J40: 0 | K40: =SUM(START:END!K40) -> 0 | L40: =SUM(START:END!L40) -> 0 | M40: =SUM(START:END!M40) -> 0 | N40: =SUM(START:END!N40) -> 0 | O40: Shawn Brown | Q40: =SUM(START:END!Q40) -> 1 | R40: =SUM(START:END!R40) -> 0 | S40: =SUM(START:END!S40) -> 0 | T40: =SUM(START:END!T40) -> 0 | U40: =SUM(START:END!U40) -> 0 | V40: =SUM(START:END!V40) -> 0 | W40: =SUM(START:END!W40) -> 0 | X40: =SUM(START:END!X40) -> 0 | Y40: =SUM(D40:X40) -> 1
B41: November 5th, 2024
B42: TOTALS
B43: NAME OF OFFICE | C43: NAME OF PERSON VOTED FOR | D43: PARTY | E43: ALLODIUM | F43: BRYANT | G43: GETTYSBURG | H43: GRAHAM | I43: HAPPPY | J43: HILL CITY #1 | K43: HILL CITY #2 | L43: HILL CITY #3 | M43: HILL CITY TWP #71 | N43: HILL CITY TWP #72 | O43: NAME OF PERSON VOTED FOR | P43: PARTY | Q43: HILL CITY TWP #73 | R43: INDIANA | S43: MILLBROOK | T43: MORLAN | U43: NICODEMUS | V43: PIONEER | W43: SOLOMON | X43: WILDHORSE | Y43: TOTAL
B44: HOSPITAL Board Pos. 4 | O44: HOSPITAL
C45: Barbara Stites | E45: =SUM(START:END!E45) -> 0 | F45: =SUM(START:END!F45) -> 0 | G45: =SUM(START:END!G45) -> 0 | H45: =SUM(START:END!H45) -> 0 | I45: =SUM(START:END!I45) -> 1 | J45: =SUM(START:END!J45) -> 0 | K45: =SUM(START:END!K45) -> 0 | L45: =SUM(START:END!L45) -> 0 | ... N45: =SUM(START:END!N45) -> 0 | O45: Barbara Stites | Q45: =SUM(START:END!Q45) -> 0 | R45: =SUM(START:END!R45) -> 0 | S45: =SUM(START:END!S45) -> 0 | T45: =SUM(START:END!T45) -> 0 | U45: =SUM(START:END!U45) -> 0 | V45: =SUM(START:END!V45) -> 0 | W45: =SUM(START:END!W45) -> 0 | X45: =SUM(START:END!X45) -> 0 | Y45: =SUM(E45:X45) -> 1
C46: Vera Garrison | E46: =SUM(START:END!E46) -> 0 | F46: =SUM(START:END!F46) -> 0 | G46: =SUM(START:END!G46) -> 0 | H46: =SUM(START:END!H46) -> 0 | I46: =SUM(START:END!I46) -> 0 | J46: =SUM(START:END!J46) -> 0 | K46: =SUM(START:END!K46) -> 0 | L46: =SUM(START:END!L46) -> 0 | ... N46: =SUM(START:END!N46) -> 0 | O46: Vera Garrison | Q46: =SUM(START:END!Q46) -> 1 | R46: =SUM(START:END!R46) -> 0 | S46: =SUM(START:END!S46) -> 0 | T46: =SUM(START:END!T46) -> 0 | U46: =SUM(START:END!U46) -> 0 | V46: =SUM(START:END!V46) -> 0 | W46: =SUM(START:END!W46) -> 0 | X46: =SUM(START:END!X46) -> 0 | Y46: =SUM(E46:X46) -> 1
C47: Jana Irby | E47: =SUM(START:END!E47) -> 0 | F47: =SUM(START:END!F47) -> 0 | G47: =SUM(START:END!G47) -> 0 | H47: =SUM(START:END!H47) -> 0 | I47: =SUM(START:END!I47) -> 0 | J47: =SUM(START:END!J47) -> 0 | K47: =SUM(START:END!K47) -> 0 | L47: =SUM(START:END!L47) -> 0 | ... N47: =SUM(START:END!N47) -> 0 | O47: Jana Irby | Q47: =SUM(START:END!Q47) -> 1 | R47: =SUM(START:END!R47) -> 0 | S47: =SUM(START:END!S47) -> 0 | T47: =SUM(START:END!T47) -> 0 | U47: =SUM(START:END!U47) -> 0 | V47: =SUM(START:END!V47) -> 0 | W47: =SUM(START:END!W47) -> 0 | X47: =SUM(START:END!X47) -> 0 | Y47: =SUM(E47:X47) -> 1
C48: Deb Hill | E48: =SUM(START:END!E48) -> 0 | F48: =SUM(START:END!F48) -> 0 | G48: =SUM(START:END!G48) -> 0 | H48: =SUM(START:END!H48) -> 0 | I48: =SUM(START:END!I48) -> 0 | J48: =SUM(START:END!J48) -> 0 | K48: =SUM(START:END!K48) -> 0 | L48: =SUM(START:END!L48) -> 0 | ... N48: =SUM(START:END!N48) -> 0 | O48: Deb Hill | Q48: =SUM(START:END!Q48) -> 0 | R48: =SUM(START:END!R48) -> 0 | S48: =SUM(START:END!S48) -> 1 | T48: =SUM(START:END!T48) -> 0 | U48: =SUM(START:END!U48) -> 0 | V48: =SUM(START:END!V48) -> 0 | W48: =SUM(START:END!W48) -> 0 | X48: =SUM(START:END!X48) -> 0 | Y48: =SUM(E48:X48) -> 1
C49: Renee Jackson | E49: =SUM(START:END!E49) -> 0 | F49: =SUM(START:END!F49) -> 0 | G49: =SUM(START:END!G49) -> 0 | H49: =SUM(START:END!H49) -> 0 | I49: =SUM(START:END!I49) -> 0 | J49: =SUM(START:END!J49) -> 0 | K49: =SUM(START:END!K49) -> 0 | L49: =SUM(START:END!L49) -> 0 | ... N49: =SUM(START:END!N49) -> 0 | O49: Renee Jackson | Q49: =SUM(START:END!Q49) -> 0 | R49: =SUM(START:END!R49) -> 0 | S49: =SUM(START:END!S49) -> 1 | T49: =SUM(START:END!T49) -> 0 | U49: =SUM(START:END!U49) -> 0 | V49: =SUM(START:END!V49) -> 0 | W49: =SUM(START:END!W49) -> 0 | X49: =SUM(START:END!X49) -> 0 | Y49: =SUM(E49:X49) -> 1
C50: Ryan Scott | E50: =SUM(START:END!E50) -> 0 | F50: =SUM(START:END!F50) -> 0 | G50: =SUM(START:END!G50) -> 0 | H50: =SUM(START:END!H50) -> 0 | I50: =SUM(START:END!I50) -> 0 | J50: =SUM(START:END!J50) -> 0 | K50: =SUM(START:END!K50) -> 0 | L50: =SUM(START:END!L50) -> 0 | ... N50: =SUM(START:END!N50) -> 0 | O50: Ryan Scott | Q50: =SUM(START:END!Q50) -> 0 | R50: =SUM(START:END!R50) -> 0 | S50: =SUM(START:END!S50) -> 1 | T50: =SUM(START:END!T50) -> 0 | U50: =SUM(START:END!U50) -> 0 | V50: =SUM(START:END!V50) -> 0 | W50: =SUM(START:END!W50) -> 0 | X50: =SUM(START:END!X50) -> 0 | Y50: =SUM(E50:X50) -> 1
C51: Sue Worcester | E51: =SUM(START:END!E51) -> 0 | F51: =SUM(START:END!F51) -> 0 | G51: =SUM(START:END!G51) -> 0 | H51: =SUM(START:END!H51) -> 0 | I51: =SUM(START:END!I51) -> 0 | J51: =SUM(START:END!J51) -> 0 | K51: =SUM(START:END!K51) -> 1 | L51: =SUM(START:END!L51) -> 1 | ... N51: =SUM(START:END!N51) -> 0 | O51: Sue Worcester | Q51: =SUM(START:END!Q51) -> 0 | R51: =SUM(START:END!R51) -> 0 | S51: =SUM(START:END!S51) -> 0 | T51: =SUM(START:END!T51) -> 0 | U51: =SUM(START:END!U51) -> 1 | V51: =SUM(START:END!V51) -> 0 | W51: =SUM(START:END!W51) -> 0 | X51: =SUM(START:END!X51) -> 1 | Y51: =SUM(U51:X51) -> 2
C52: Esther Clark | E52: =SUM(START:END!E52) -> 0 | F52: =SUM(START:END!F52) -> 0 | G52: =SUM(START:END!G52) -> 0 | H52: =SUM(START:END!H52) -> 0 | I52: =SUM(START:END!I52) -> 0 | J52: =SUM(START:END!J52) -> 0 | K52: =SUM(START:END!K52) -> 0 | L52: =SUM(START:END!L52) -> 0 | ... N52: =SUM(START:END!N52) -> 0 | O52: Esther Clark | Q52: =SUM(START:END!Q52) -> 0 | R52: =SUM(START:END!R52) -> 0 | S52: =SUM(START:END!S52) -> 0 | T52: =SUM(START:END!T52) -> 0 | U52: =SUM(START:END!U52) -> 1 | V52: =SUM(START:END!V52) -> 0 | W52: =SUM(START:END!W52) -> 0 | X52: =SUM(START:END!X52) -> 0 | Y52: =SUM(U52:X52) -> 1
C53: Tessa Tremblay | E53: =SUM(START:END!E53) -> 0 | F53: =SUM(START:END!F53) -> 0 | G53: =SUM(START:END!G53) -> 0 | H53: =SUM(START:END!H53) -> 0 | I53: =SUM(START:END!I53) -> 0 | J53: =SUM(START:END!J53) -> 0 | K53: =SUM(START:END!K53) -> 0 | L53: =SUM(START:END!L53) -> 0 | ... N53: =SUM(START:END!N53) -> 0 | O53: Tessa Tremblay | Q53: =SUM(START:END!Q53) -> 0 | R53: =SUM(START:END!R53) -> 0 | S53: =SUM(START:END!S53) -> 0 | T53: =SUM(START:END!T53) -> 0 | U53: =SUM(START:END!U53) -> 0 | V53: =SUM(START:END!V53) -> 0 | W53: =SUM(START:END!W53) -> 1 | X53: =SUM(START:END!X53) -> 0 | Y53: =SUM(E53:X53) -> 1
...

Sheet Abstract
B1: Abstract of Votes Cast at the Primary Election in | N1: Abstract of Votes Cast at the General Election in
B2: Graham County Kansas, on the 5th day of November, 2024 | N2: Graham County Kansas, on the 5th day of November, 2024
B3: Number of Voters Voting | C3: 1317
B4: Registered Voters | C4: 1808
B5: Turnout | C5: 0.73
B6: NAME OF OFFICE | C6: NAME OF PERSON VOTED FOR | D6: ALLODIUM | E6: BRYANT | F6: GETTYSBURG | G6: GRAHAM | H6: HAPPPY | I6: HILL CITY #1 | J6: HILL CITY #2 | K6: HILL CITY #3 | L6: HILL CITY TWP #71 | M6: HILL CITY TWP #72 | N6: NAME OF PERSON VOTED FOR | O6: HILL CITY TWP #73 | P6: INDIANA | Q6: MILLBROOK | R6: MORLAN | S6: NICODEMUS | T6: PIONEER | U6: SOLOMON | V6: WILDHORSE | W6: TOTAL | X6: PROVISIONAL | Y6: TOTAL
B7: HOSPITAL Board Pos. 4 | N7: HOSPITAL
C8: Michelle Smee | D8: =SUM(START:END!E5) -> 2 | F8: =SUM(START:END!G5) -> 5 | G8: =SUM(START:END!H5) -> 4 | H8: =SUM(START:END!I5) -> 2 | I8: =SUM(START:END!J5) -> 9 | J8: =SUM(START:END!K5) -> 58 | K8: =SUM(START:END!L5) -> 7 | M8: =SUM(START:END!N5) -> 7 | N8: Michelle Smee | O8: =SUM(START:END!Q5) -> 4 | P8: =SUM(START:END!R5) -> 1 | Q8: =SUM(START:END!S5) -> 5 | R8: =SUM(START:END!T5) -> 3 | S8: =SUM(START:END!U5) -> 1 | T8: =SUM(START:END!V5) -> 7 | U8: =SUM(START:END!W5) -> 3 | V8: =SUM(START:END!X5) -> 10 | W8: =SUM(D8:V8) -> 128 | X8: 1 | Y8: =SUM(W8:X8) -> 129
C9: Nikki Presley | D9: =SUM(START:END!E6) -> 1 | M9: =SUM(START:END!N6) -> 0 | N9: Nikki Presley | W9: =SUM(D9:V9) -> 1 | Y9: =SUM(W9:X9) -> 1
C10: T. Treas | E10: =SUM(START:END!F7) -> 1 | M10: =SUM(START:END!N7) -> 0 | N10: T. Treas | W10: =SUM(D10:V10) -> 1 | Y10: =SUM(W10:X10) -> 1
C11: Mark Fergeson | E11: =SUM(START:END!F8) -> 2 | M11: =SUM(START:END!N8) -> 0 | N11: Mark Fergeson | W11: =SUM(D11:V11) -> 2 | Y11: =SUM(W11:X11) -> 2
C12: Cody Keiswetter | G12: =SUM(START:END!H9) -> 1 | M12: =SUM(START:END!N9) -> 0 | N12: Cody Keiswetter | W12: =SUM(D12:V12) -> 1 | Y12: =SUM(W12:X12) -> 1
C13: Connie Gish | H13: =SUM(START:END!I10) -> 1 | K13: =SUM(START:END!L10) -> 1 | M13: =SUM(START:END!N10) -> 0 | N13: Connie Gish | Q13: =SUM(START:END!S10) -> 1 | W13: =SUM(D13:V13) -> 3 | Y13: =SUM(W13:X13) -> 3
C14: Michelle Billips | I14: =SUM(START:END!J11) -> 1 | K14: =SUM(START:END!L11) -> 1 | M14: =SUM(START:END!N11) -> 0 | N14: Michelle Billips | W14: =SUM(D14:V14) -> 2 | Y14: =SUM(W14:X14) -> 2
C15: Rhonda Goddard | I15: =SUM(START:END!J12) -> 1 | M15: =SUM(START:END!N12) -> 0 | N15: Rhonda Goddard | W15: =SUM(D15:V15) -> 1 | Y15: =SUM(W15:X15) -> 1
C16: Chris Smee | I16: =SUM(START:END!J13) -> 1 | K16: =SUM(START:END!L13) -> 1 | M16: =SUM(START:END!N13) -> 0 | N16: Chris Smee | W16: =SUM(D16:V16) -> 2 | Y16: =SUM(W16:X16) -> 2
C17: Dan Irby | I17: =SUM(START:END!J14) -> 1 | J17: =SUM(START:END!K14) -> 3 | M17: =SUM(START:END!N14) -> 1 | N17: Dan Irby | Q17: =SUM(START:END!S14) -> 1 | U17: =SUM(START:END!W14) -> 1 | W17: =SUM(D17:V17) -> 7 | Y17: =SUM(W17:X17) -> 7
C18: Dan Worcester | J18: =SUM(START:END!K15) -> 1 | M18: =SUM(START:END!N15) -> 0 | N18: Dan Worcester | W18: =SUM(D18:V18) -> 1 | Y18: =SUM(W18:X18) -> 1
C19: David Atkins | J19: =SUM(START:END!K16) -> 1 | M19: =SUM(START:END!N16) -> 0 | N19: David Atkins | U19: =SUM(START:END!W16) -> 1 | W19: =SUM(D19:V19) -> 2 | Y19: =SUM(W19:X19) -> 2
C20: Marcy Gansel | J20: =SUM(START:END!K17) -> 1 | M20: =SUM(START:END!N17) -> 0 | N20: Marcy Gansel | W20: =SUM(D20:V20) -> 1 | Y20: =SUM(W20:X20) -> 1
C21: Cindy Underhill | J21: =SUM(START:END!K18) -> 1 | K21: =SUM(START:END!L18) -> 1 | L21: =SUM(START:END!M18) -> 1 | M21: =SUM(START:END!N18) -> 1 | N21: Cindy Underhill | W21: =SUM(D21:V21) -> 4 | Y21: =SUM(W21:X21) -> 4
C22: Kay Money | J22: =SUM(START:END!K19) -> 1 | M22: =SUM(START:END!N19) -> 0 | N22: Kay Money | V22: =SUM(START:END!X19) -> 1 | W22: =SUM(D22:V22) -> 2 | Y22: =SUM(W22:X22) -> 2
C23: Kimberly Kinderknecht | J23: =SUM(START:END!K20) -> 1 | M23: =SUM(START:END!N20) -> 0 | N23: Kimberly Kinderknecht | W23: =SUM(D23:V23) -> 1 | Y23: =SUM(W23:X23) -> 1
C24: Ethan Edwards | J24: =SUM(START:END!K21) -> 1 | M24: =SUM(START:END!N21) -> 0 | N24: Ethan Edwards | W24: =SUM(D24:V24) -> 1 | Y24: =SUM(W24:X24) -> 1
C25: Ron Radcliffe | J25: =SUM(START:END!K22) -> 1 | M25: =SUM(START:END!N22) -> 0 | N25: Ron Radcliffe | W25: =SUM(D25:V25) -> 1 | Y25: =SUM(W25:X25) -> 1
C26: Joyce Reese | J26: =SUM(START:END!K23) -> 1 | M26: =SUM(START:END!N23) -> 0 | N26: Joyce Reese | W26: =SUM(D26:V26) -> 1 | Y26: =SUM(W26:X26) -> 1
C27: Lance Post | J27: =SUM(START:END!K24) -> 1 | K27: =SUM(START:END!L24) -> 3 | M27: =SUM(START:END!N24) -> 1 | N27: Lance Post | W27: =SUM(D27:V27) -> 5 | Y27: =SUM(W27:X27) -> 5
C28: Saundra Nickelson | J28: =SUM(START:END!K25) -> 1 | M28: =SUM(START:END!N25) -> 0 | N28: Saundra Nickelson | W28: =SUM(D28:V28) -> 1 | Y28: =SUM(W28:X28) -> 1
C29: Reggie Jordan | J29: =SUM(START:END!K26) -> 1 | M29: =SUM(START:END!N26) -> 0 | N29: Reggie Jordan | W29: =SUM(D29:V29) -> 1 | Y29: =SUM(W29:X29) -> 1
O30: STATE OF KANSAS,
O31: Graham County, ss.
P32: We, the undersigned, members of the County Board of Canvassers for said County, do hereby
O33: certify that the foregoing abstract of votes cast at the General election held in Graham County on the 5th day of November A.D. 2024, is
O34: true and correct as shown by the returns of said election on file in the office of the County Election officer and canvassed by us
O35: this 15th day of November A.D. 2024.
O36: Witness our hands, this 15th day of November A.D. 2024.
O37: Attest: | S37: _____________________________
O38: _____________________________ | S38: _____________________________
O39: County Election Officer. | S39: _____________________________
T40: County Board of Canvassers.
...
